<?xml version="1.0"?>
<!--
  Robotic Horse — Gazebo / ROS2 URDF
  ===================================
  This is the Gazebo-compatible version of the robot description.
  It extends the base URDF with:
    • <ros2_control> hardware interface tags  (17 controlled joints)
    • <gazebo> plugin tag  (loads gazebo_ros2_control)
    • <gazebo> material + contact tags per link

  Leg layout (top view):
      FL –––– FR
      |        |
      RL –––– RR

  Controlled joints (17 total, QDD actuated):
      spine_yaw_joint              — spine lateral bend       (position ctrl)
      {fl,fr,rl,rr}_hip_joint     — lateral hip yaw          (position ctrl)
      {fl,fr,rl,rr}_thigh_joint   — hip flexion/extension    (position ctrl)
      {fl,fr,rl,rr}_knee_joint    — stifle/elbow flexion     (position ctrl)
      {fl,fr,rl,rr}_cannon_joint  — hock/fetlock (coupled)   (position ctrl)

  Physical parameters (edit here and in ros2_control.yaml):
    Body mass  : 107 kg (QDD motors + frame + decoration)
    Front thigh: 0.38 m,  4.0 kg  /  Rear thigh: 0.50 m,  5.0 kg
    Front shank: 0.34 m,  3.5 kg  /  Rear shank: 0.45 m,  4.0 kg
    Front cannon: 0.18 m, 1.0 kg  /  Rear cannon: 0.22 m, 1.2 kg
    Front foot: r=0.05 m, 0.4 kg  /  Rear foot: r=0.06 m, 0.5 kg
-->
<robot name="robotic_horse" xmlns:xacro="http://www.ros.org/wiki/xacro">

  <!-- ═══════════════════════════════════════════════════════
       MATERIALS
  ═══════════════════════════════════════════════════════ -->
  <material name="dark_grey">  <color rgba="0.20 0.20 0.20 1"/></material>
  <material name="orange">     <color rgba="0.90 0.40 0.00 1"/></material>
  <material name="light_grey"> <color rgba="0.70 0.70 0.70 1"/></material>
  <material name="black">      <color rgba="0.05 0.05 0.05 1"/></material>
  <material name="silver">     <color rgba="0.75 0.75 0.80 1"/></material>
  <material name="body_panel"> <color rgba="0.25 0.25 0.30 1"/></material>
  <material name="wood">       <color rgba="0.55 0.35 0.15 1"/></material>
  <material name="iron">       <color rgba="0.28 0.28 0.28 1"/></material>
  <material name="red_velvet"> <color rgba="0.60 0.05 0.05 1"/></material>

  <!-- ═══════════════════════════════════════════════════════
       IMU SENSOR  — provides body orientation for self-balance
       Published on /imu/data (bridged from gz transport).
       Pitch (Y) used to adapt foot step heights per leg.
       Roll  (X) used to adapt hip Z splay at idle.
  ═══════════════════════════════════════════════════════ -->

  <!-- IMU sensor on base_link — publishes body orientation for balance -->
  <gazebo reference="base_link">
    <sensor name="imu_sensor" type="imu">
      <always_on>true</always_on>
      <update_rate>100</update_rate>
      <topic>/imu/data</topic>
      <imu>
        <angular_velocity>
          <x><noise type="gaussian"><mean>0</mean><stddev>0.001</stddev></noise></x>
          <y><noise type="gaussian"><mean>0</mean><stddev>0.001</stddev></noise></y>
          <z><noise type="gaussian"><mean>0</mean><stddev>0.001</stddev></noise></z>
        </angular_velocity>
        <linear_acceleration>
          <x><noise type="gaussian"><mean>0</mean><stddev>0.01</stddev></noise></x>
          <y><noise type="gaussian"><mean>0</mean><stddev>0.01</stddev></noise></y>
          <z><noise type="gaussian"><mean>0</mean><stddev>0.01</stddev></noise></z>
        </linear_acceleration>
      </imu>
    </sensor>
  </gazebo>



  <!-- ═══════════════════════════════════════════════════════
       BASE LINK
  ═══════════════════════════════════════════════════════ -->
  <!-- Body mass ~107 kg: motors(48)+frame(38)+electronics(8)+decoration(8)+legs(5).
       Inertia (107 kg, 1.80x0.88x0.85 m box): Ixx=13.35, Iyy=35.33, Izz=35.80 kg·m²
       Scaled 1.36× from real Highland cow (110cm withers → 150cm) -->
  <!-- base_link = REAR body half (haunches/lumbar).
       Rear legs (RL/RR) and carriage hitch attach here.
       IMU stays on base_link for balance sensing. -->
  <link name="base_link">
    <inertial>
      <mass value="48.0"/>
      <origin xyz="0.45 0 0" rpy="0 0 0"/>
      <inertia ixx="6.0" iyy="6.1" izz="6.3" ixy="0" ixz="0" iyz="0"/>
    </inertial>
    <!-- Rear barrel half -->
    <visual>
      <origin xyz="0.45 0 0" rpy="0 0 0"/>
      <geometry><box size="0.90 0.88 0.75"/></geometry>
      <material name="body_panel"/>
    </visual>
    <!-- Rump (back — at +X) -->
    <visual>
      <origin xyz="0.55 0 0.425" rpy="0 0 0"/>
      <geometry><box size="0.40 0.76 0.10"/></geometry>
      <material name="body_panel"/>
    </visual>

    <collision>
      <origin xyz="0.45 0 0" rpy="0 0 0"/>
      <geometry><box size="0.90 0.88 0.85"/></geometry>
    </collision>
  </link>
  <gazebo reference="base_link">
    <material>Gazebo/DarkGrey</material>
  </gazebo>

  <!-- ═══════════════════════════════════════════════════════
       SPINE YAW JOINT — articulated spine for turning
       Connects rear body (base_link) to front body (front_body_link).
       Z-axis rotation allows lateral bending like a real quadruped.
       This is the PRIMARY turning mechanism — combined with
       differential stride length for smooth, natural turns.
  ═══════════════════════════════════════════════════════ -->
  <joint name="spine_yaw_joint" type="revolute">
    <parent link="base_link"/><child link="front_body_link"/>
    <origin xyz="0 0 0" rpy="0 0 0"/>
    <axis xyz="0 0 1"/>
    <limit lower="-0.30" upper="0.30" effort="500" velocity="1.5"/>
    <dynamics damping="12.0" friction="1.0"/>
  </joint>

  <!-- front_body_link = FRONT body half (thorax/shoulders).
       Front legs (FL/FR) and head/neck attach here.
       55% of body mass (bovine weight distribution). -->
  <link name="front_body_link">
    <inertial>
      <mass value="59.0"/>
      <origin xyz="-0.45 0 0" rpy="0 0 0"/>
      <inertia ixx="7.4" iyy="7.5" izz="7.8" ixy="0" ixz="0" iyz="0"/>
    </inertial>
    <!-- Front barrel half -->
    <visual>
      <origin xyz="-0.45 0 0" rpy="0 0 0"/>
      <geometry><box size="0.90 0.88 0.75"/></geometry>
      <material name="body_panel"/>
    </visual>
    <!-- Withers rise (front shoulder hump) -->
    <visual>
      <origin xyz="-0.50 0 0.475" rpy="0 0 0"/>
      <geometry><box size="0.55 0.78 0.20"/></geometry>
      <material name="body_panel"/>
    </visual>
    <!-- Chest extension (brisket, front-bottom) -->
    <visual>
      <origin xyz="-0.55 0 -0.435" rpy="0 0 0"/>
      <geometry><box size="0.40 0.72 0.12"/></geometry>
      <material name="body_panel"/>
    </visual>

    <collision>
      <origin xyz="-0.45 0 0" rpy="0 0 0"/>
      <geometry><box size="0.90 0.88 0.85"/></geometry>
    </collision>
  </link>
  <gazebo reference="front_body_link">
    <material>Gazebo/DarkGrey</material>
  </gazebo>

  <!-- ─── HIGHLAND COW HEAD (articulated) ───────────────────── -->
  <!-- Neck: yaw + pitch joints for head motion
       Head: jaw (open/close), eyes (left/right pan)
       Small servos — total head assembly ~6.5 kg
       Attached to front_body_link (thorax) -->

  <!-- Neck yaw — swivel left/right (head faces -X direction of travel) -->
  <link name="neck_yaw_link">
    <inertial><mass value="0.5"/><origin xyz="0 0 0" rpy="0 0 0"/>
      <inertia ixx="0.001" iyy="0.001" izz="0.001" ixy="0" ixz="0" iyz="0"/></inertial>
  </link>
  <joint name="neck_yaw_joint" type="revolute">
    <parent link="front_body_link"/><child link="neck_yaw_link"/>
    <origin xyz="-0.85 0 0.42" rpy="0 0 3.14159"/>
    <axis xyz="0 0 1"/>
    <limit lower="-0.6" upper="0.6" effort="15.0" velocity="2.0"/>
    <dynamics damping="2.0" friction="0.5"/>
  </joint>

  <!-- Neck pitch — nod up/down -->
  <link name="neck_link">
    <inertial><mass value="3.0"/><origin xyz="0.10 0 0" rpy="0 0 0"/>
      <inertia ixx="0.015" iyy="0.015" izz="0.008" ixy="0" ixz="0" iyz="0"/></inertial>
    <visual><origin xyz="0.10 0 0" rpy="0 0 0">
      </origin><geometry><box size="0.22 0.24 0.26"/></geometry><material name="body_panel"/></visual>
    <collision><origin xyz="0.10 0 0" rpy="0 0 0">
      </origin><geometry><box size="0.22 0.24 0.26"/></geometry></collision>
  </link>
  <joint name="neck_pitch_joint" type="revolute">
    <parent link="neck_yaw_link"/><child link="neck_link"/>
    <origin xyz="0 0 0" rpy="0 -0.10 0"/>
    <axis xyz="0 1 0"/>
    <limit lower="-0.5" upper="0.4" effort="20.0" velocity="2.0"/>
    <dynamics damping="3.0" friction="0.5"/>
  </joint>
  <gazebo reference="neck_link"><material>Gazebo/Brown</material></gazebo>

  <!-- Head link — skull, muzzle, nose, horns (same geometry as before) -->
  <link name="head_link">
    <inertial><mass value="2.0"/><origin xyz="0.15 0 0" rpy="0 0 0"/>
      <inertia ixx="0.016" iyy="0.018" izz="0.013" ixy="0" ixz="0" iyz="0"/></inertial>
    <!-- Skull — broad Highland Cow head -->
    <visual><origin xyz="0 0 0" rpy="0 0 0">
      </origin><geometry><box size="0.38 0.34 0.28"/></geometry><material name="body_panel"/></visual>
    <!-- Muzzle extending forward -->
    <visual><origin xyz="0.25 0 -0.04" rpy="0 0 0">
      </origin><geometry><box size="0.18 0.20 0.16"/></geometry><material name="body_panel"/></visual>
    <!-- LEFT horn: wide sweep outward + slight upward curl — iconic Highland Cow -->
    <visual><origin xyz="-0.06 0.20 0.11" rpy="0.20 0.25 1.30">
      </origin><geometry><cylinder radius="0.025" length="0.50"/></geometry><material name="silver"/></visual>
    <!-- RIGHT horn -->
    <visual><origin xyz="-0.06 -0.20 0.11" rpy="-0.20 -0.25 -1.30">
      </origin><geometry><cylinder radius="0.025" length="0.50"/></geometry><material name="silver"/></visual>
    <collision><origin xyz="0.10 0 0" rpy="0 0 0">
      </origin><geometry><box size="0.60 0.34 0.30"/></geometry></collision>
  </link>
  <joint name="head_nod_joint" type="revolute">
    <parent link="neck_link"/><child link="head_link"/>
    <origin xyz="0.20 0 0" rpy="0 0.10 0"/>
    <axis xyz="0 1 0"/>
    <limit lower="-0.3" upper="0.3" effort="8.0" velocity="3.0"/>
    <dynamics damping="1.0" friction="0.3"/>
  </joint>
  <gazebo reference="head_link"><material>Gazebo/Brown</material></gazebo>

  <!-- Jaw — opens downward (mouth) -->
  <link name="jaw_link">
    <inertial><mass value="0.3"/><origin xyz="0.06 0 -0.03" rpy="0 0 0"/>
      <inertia ixx="0.0003" iyy="0.0004" izz="0.0003" ixy="0" ixz="0" iyz="0"/></inertial>
    <visual><origin xyz="0.06 0 -0.03" rpy="0 0 0">
      </origin><geometry><box size="0.14 0.16 0.06"/></geometry><material name="body_panel"/></visual>
    <!-- Nose on jaw -->
    <visual><origin xyz="0.12 0 -0.01" rpy="0 0 0">
      </origin><geometry><box size="0.04 0.10 0.05"/></geometry><material name="black"/></visual>
    <collision><origin xyz="0.06 0 -0.03" rpy="0 0 0">
      </origin><geometry><box size="0.14 0.16 0.06"/></geometry></collision>
  </link>
  <joint name="jaw_joint" type="revolute">
    <parent link="head_link"/><child link="jaw_link"/>
    <origin xyz="0.20 0 -0.10" rpy="0 0 0"/>
    <axis xyz="0 1 0"/>
    <limit lower="-0.35" upper="0.0" effort="3.0" velocity="4.0"/>
    <dynamics damping="0.5" friction="0.1"/>
  </joint>
  <gazebo reference="jaw_link"><material>Gazebo/Brown</material></gazebo>

  <!-- Left eye -->
  <link name="left_eye_link">
    <inertial><mass value="0.05"/><origin xyz="0 0 0" rpy="0 0 0"/>
      <inertia ixx="0.00001" iyy="0.00001" izz="0.00001" ixy="0" ixz="0" iyz="0"/></inertial>
    <visual><origin xyz="0 0 0" rpy="0 0 0">
      </origin><geometry><sphere radius="0.025"/></geometry><material name="black"/></visual>
  </link>
  <joint name="left_eye_joint" type="revolute">
    <parent link="head_link"/><child link="left_eye_link"/>
    <origin xyz="0.14 0.14 0.04" rpy="0 0 0"/>
    <axis xyz="0 0 1"/>
    <limit lower="-0.4" upper="0.4" effort="1.0" velocity="5.0"/>
    <dynamics damping="0.1" friction="0.05"/>
  </joint>
  <gazebo reference="left_eye_link"><material>Gazebo/Black</material></gazebo>

  <!-- Right eye -->
  <link name="right_eye_link">
    <inertial><mass value="0.05"/><origin xyz="0 0 0" rpy="0 0 0"/>
      <inertia ixx="0.00001" iyy="0.00001" izz="0.00001" ixy="0" ixz="0" iyz="0"/></inertial>
    <visual><origin xyz="0 0 0" rpy="0 0 0">
      </origin><geometry><sphere radius="0.025"/></geometry><material name="black"/></visual>
  </link>
  <joint name="right_eye_joint" type="revolute">
    <parent link="head_link"/><child link="right_eye_link"/>
    <origin xyz="0.14 -0.14 0.04" rpy="0 0 0"/>
    <axis xyz="0 0 1"/>
    <limit lower="-0.4" upper="0.4" effort="1.0" velocity="5.0"/>
    <dynamics damping="0.1" friction="0.05"/>
  </joint>
  <gazebo reference="right_eye_link"><material>Gazebo/Black</material></gazebo>

  <!-- Left eyelid (blink) -->
  <link name="left_eyelid_link">
    <inertial><mass value="0.02"/><origin xyz="0 0 0" rpy="0 0 0"/>
      <inertia ixx="0.000001" iyy="0.000001" izz="0.000001" ixy="0" ixz="0" iyz="0"/></inertial>
    <visual><origin xyz="0.005 0 0.012" rpy="0 0 0">
      </origin><geometry><box size="0.01 0.05 0.025"/></geometry><material name="body_panel"/></visual>
  </link>
  <joint name="left_eyelid_joint" type="revolute">
    <parent link="head_link"/><child link="left_eyelid_link"/>
    <origin xyz="0.16 0.14 0.06" rpy="0 0 0"/>
    <axis xyz="0 1 0"/>
    <limit lower="-0.8" upper="0.0" effort="0.5" velocity="8.0"/>
    <dynamics damping="0.05" friction="0.02"/>
  </joint>
  <gazebo reference="left_eyelid_link"><material>Gazebo/Brown</material></gazebo>

  <!-- Right eyelid (blink) -->
  <link name="right_eyelid_link">
    <inertial><mass value="0.02"/><origin xyz="0 0 0" rpy="0 0 0"/>
      <inertia ixx="0.000001" iyy="0.000001" izz="0.000001" ixy="0" ixz="0" iyz="0"/></inertial>
    <visual><origin xyz="0.005 0 0.012" rpy="0 0 0">
      </origin><geometry><box size="0.01 0.05 0.025"/></geometry><material name="body_panel"/></visual>
  </link>
  <joint name="right_eyelid_joint" type="revolute">
    <parent link="head_link"/><child link="right_eyelid_link"/>
    <origin xyz="0.16 -0.14 0.06" rpy="0 0 0"/>
    <axis xyz="0 1 0"/>
    <limit lower="-0.8" upper="0.0" effort="0.5" velocity="8.0"/>
    <dynamics damping="0.05" friction="0.02"/>
  </joint>
  <gazebo reference="right_eyelid_link"><material>Gazebo/Brown</material></gazebo>

  <!-- ═══════════════════════════════════════════════════════
       LEG LINKS & JOINTS  (macro-expanded for FL/FR/RL/RR)
  ═══════════════════════════════════════════════════════ -->

  <!-- ── FRONT-LEFT ── -->
  <link name="fl_hip_link">
    <inertial><mass value="4.0"/><origin xyz="0 0 0" rpy="0 0 0"/>
      <inertia ixx="0.012" iyy="0.012" izz="0.007" ixy="0" ixz="0" iyz="0"/></inertial>
    <visual><origin xyz="0 0 -0.06" rpy="0 0 0"/>
      <geometry><cylinder radius="0.05" length="0.12"/></geometry><material name="silver"/></visual>
    <collision><origin xyz="0 0 -0.07" rpy="0 0 0"/>
      <geometry><cylinder radius="0.04" length="0.10"/></geometry></collision>
  </link>
  <joint name="fl_hip_joint" type="revolute">
    <parent link="front_body_link"/><child link="fl_hip_link"/>
    <origin xyz="0.65 0.44 -0.15" rpy="0 0 0"/>
    <axis xyz="0 0 1"/>
    <limit lower="-0.35" upper="0.35" effort="200" velocity="2.0"/>
    <dynamics damping="2.5" friction="0.3"/>
  </joint>
  <gazebo reference="fl_hip_link"><material>Gazebo/Grey</material></gazebo>

  <link name="fl_thigh_link">
    <inertial><mass value="4.0"/><origin xyz="0 0 -0.19" rpy="0 0 0"/>
      <inertia ixx="0.0496" iyy="0.0496" izz="0.0032" ixy="0" ixz="0" iyz="0"/></inertial>
    <visual><origin xyz="0 0 -0.19" rpy="0 0 0"/>
      <geometry><cylinder radius="0.04" length="0.38"/></geometry><material name="orange"/></visual>
    <collision><origin xyz="0 0 -0.19" rpy="0 0 0">
      </origin><geometry><cylinder radius="0.04" length="0.38"/></geometry></collision>
  </link>
  <joint name="fl_thigh_joint" type="revolute">
    <parent link="fl_hip_link"/><child link="fl_thigh_link"/>
    <origin xyz="0 0 -0.10" rpy="0 0 0"/><axis xyz="0 1 0"/>
    <limit lower="-0.30" upper="1.20" effort="500" velocity="3.0"/>
    <dynamics damping="2.5" friction="0.3"/>
  </joint>
  <gazebo reference="fl_thigh_link"><material>Gazebo/Orange</material></gazebo>

  <link name="fl_shank_link">
    <inertial><mass value="3.5"/><origin xyz="0 0 -0.17" rpy="0 0 0"/>
      <inertia ixx="0.0348" iyy="0.0348" izz="0.0021" ixy="0" ixz="0" iyz="0"/></inertial>
    <visual><origin xyz="0 0 -0.17" rpy="0 0 0">
      </origin><geometry><cylinder radius="0.035" length="0.34"/></geometry><material name="dark_grey"/></visual>
    <collision><origin xyz="0 0 -0.17" rpy="0 0 0">
      </origin><geometry><cylinder radius="0.035" length="0.34"/></geometry></collision>
  </link>
  <joint name="fl_knee_joint" type="revolute">
    <parent link="fl_thigh_link"/><child link="fl_shank_link"/>
    <origin xyz="0 0 -0.38" rpy="0 0 0"/><axis xyz="0 1 0"/>
    <limit lower="-1.80" upper="-0.10" effort="800" velocity="5.0"/>
    <dynamics damping="3.5" friction="0.3"/>
  </joint>
  <gazebo reference="fl_shank_link"><material>Gazebo/DarkGrey</material></gazebo>

  <!-- Cannon bone (metatarsal/metacarpal): pantograph-kept near vertical -->
  <link name="fl_cannon_link">
    <inertial><mass value="1.0"/><origin xyz="0 0 -0.09" rpy="0 0 0"/>
      <inertia ixx="0.0028" iyy="0.0028" izz="0.0003" ixy="0" ixz="0" iyz="0"/></inertial>
    <visual><origin xyz="0 0 -0.09" rpy="0 0 0"/>
      <geometry><cylinder radius="0.025" length="0.18"/></geometry><material name="dark_grey"/></visual>
    <collision><origin xyz="0 0 -0.09" rpy="0 0 0"/>
      <geometry><cylinder radius="0.025" length="0.18"/></geometry></collision>
  </link>
  <joint name="fl_cannon_joint" type="revolute">
    <parent link="fl_shank_link"/><child link="fl_cannon_link"/>
    <origin xyz="0 0 -0.34" rpy="0 0 0"/><axis xyz="0 1 0"/>
    <limit lower="-2.0" upper="2.0" effort="100" velocity="6.0"/>
    <dynamics damping="1.0" friction="0.1"/>
  </joint>
  <gazebo reference="fl_cannon_link"><material>Gazebo/DarkGrey</material></gazebo>

    <link name="fl_foot_link">
    <inertial><mass value="0.4"/><origin xyz="0 0 0" rpy="0 0 0"/>
      <inertia ixx="0.00040" iyy="0.00040" izz="0.00040" ixy="0" ixz="0" iyz="0"/></inertial>
    <visual><origin xyz="0 0 0" rpy="0 0 0"/>
      <geometry><sphere radius="0.05"/></geometry><material name="black"/></visual>
    <collision><origin xyz="0 0 0" rpy="0 0 0"/>
      <geometry><sphere radius="0.05"/></geometry></collision>
  </link>
  <joint name="fl_foot_joint" type="fixed">
    <parent link="fl_cannon_link"/><child link="fl_foot_link"/>
    <origin xyz="0 0 -0.18" rpy="0 0 0"/>
  </joint>
  <gazebo reference="fl_foot_link">
    <material>Gazebo/FlatBlack</material>
    <kp>1000000.0</kp><kd>200.0</kd>
    <mu1>2.0</mu1><mu2>2.0</mu2>
    <minDepth>0.005</minDepth>
  </gazebo>

  <!-- ── FRONT-RIGHT ── -->
  <link name="fr_hip_link">
    <inertial><mass value="4.0"/><origin xyz="0 0 0" rpy="0 0 0"/>
      <inertia ixx="0.012" iyy="0.012" izz="0.007" ixy="0" ixz="0" iyz="0"/></inertial>
    <visual><origin xyz="0 0 -0.06" rpy="0 0 0"/>
      <geometry><cylinder radius="0.05" length="0.12"/></geometry><material name="silver"/></visual>
    <collision><origin xyz="0 0 -0.05" rpy="0 0 0">
      </origin><geometry><cylinder radius="0.04" length="0.10"/></geometry></collision>
  </link>
  <joint name="fr_hip_joint" type="revolute">
    <parent link="front_body_link"/><child link="fr_hip_link"/>
    <origin xyz="0.65 -0.44 -0.15" rpy="0 0 0"/>
    <axis xyz="0 0 1"/>
    <limit lower="-0.35" upper="0.35" effort="200" velocity="2.0"/>
    <dynamics damping="2.5" friction="0.3"/>
  </joint>
  <gazebo reference="fr_hip_link"><material>Gazebo/Grey</material></gazebo>
  <link name="fr_thigh_link">
    <inertial><mass value="4.0"/><origin xyz="0 0 -0.19" rpy="0 0 0"/>
      <inertia ixx="0.0496" iyy="0.0496" izz="0.0032" ixy="0" ixz="0" iyz="0"/></inertial>
    <visual><origin xyz="0 0 -0.19" rpy="0 0 0"/>
      <geometry><cylinder radius="0.04" length="0.38"/></geometry><material name="orange"/></visual>
    <collision><origin xyz="0 0 -0.19" rpy="0 0 0">
      </origin><geometry><cylinder radius="0.04" length="0.38"/></geometry></collision>
  </link>
  <joint name="fr_thigh_joint" type="revolute">
    <parent link="fr_hip_link"/><child link="fr_thigh_link"/>
    <origin xyz="0 0 -0.10" rpy="0 0 0"/><axis xyz="0 1 0"/>
    <limit lower="-0.30" upper="1.20" effort="500" velocity="3.0"/>
    <dynamics damping="2.5" friction="0.3"/>
  </joint>
  <gazebo reference="fr_thigh_link"><material>Gazebo/Orange</material></gazebo>
  <link name="fr_shank_link">
    <inertial><mass value="3.5"/><origin xyz="0 0 -0.17" rpy="0 0 0"/>
      <inertia ixx="0.0348" iyy="0.0348" izz="0.0021" ixy="0" ixz="0" iyz="0"/></inertial>
    <visual><origin xyz="0 0 -0.17" rpy="0 0 0">
      </origin><geometry><cylinder radius="0.035" length="0.34"/></geometry><material name="dark_grey"/></visual>
    <collision><origin xyz="0 0 -0.17" rpy="0 0 0">
      </origin><geometry><cylinder radius="0.035" length="0.34"/></geometry></collision>
  </link>
  <joint name="fr_knee_joint" type="revolute">
    <parent link="fr_thigh_link"/><child link="fr_shank_link"/>
    <origin xyz="0 0 -0.38" rpy="0 0 0"/><axis xyz="0 1 0"/>
    <limit lower="-1.80" upper="-0.10" effort="800" velocity="5.0"/>
    <dynamics damping="3.5" friction="0.3"/>
  </joint>
  <gazebo reference="fr_shank_link"><material>Gazebo/DarkGrey</material></gazebo>
  <!-- Cannon bone (metatarsal/metacarpal): pantograph-kept near vertical -->
  <link name="fr_cannon_link">
    <inertial><mass value="1.0"/><origin xyz="0 0 -0.09" rpy="0 0 0"/>
      <inertia ixx="0.0028" iyy="0.0028" izz="0.0003" ixy="0" ixz="0" iyz="0"/></inertial>
    <visual><origin xyz="0 0 -0.09" rpy="0 0 0"/>
      <geometry><cylinder radius="0.025" length="0.18"/></geometry><material name="dark_grey"/></visual>
    <collision><origin xyz="0 0 -0.09" rpy="0 0 0"/>
      <geometry><cylinder radius="0.025" length="0.18"/></geometry></collision>
  </link>
  <joint name="fr_cannon_joint" type="revolute">
    <parent link="fr_shank_link"/><child link="fr_cannon_link"/>
    <origin xyz="0 0 -0.34" rpy="0 0 0"/><axis xyz="0 1 0"/>
    <limit lower="-2.0" upper="2.0" effort="100" velocity="6.0"/>
    <dynamics damping="1.0" friction="0.1"/>
  </joint>
  <gazebo reference="fr_cannon_link"><material>Gazebo/DarkGrey</material></gazebo>

    <link name="fr_foot_link">
    <inertial><mass value="0.4"/><origin xyz="0 0 0" rpy="0 0 0"/>
      <inertia ixx="0.00040" iyy="0.00040" izz="0.00040" ixy="0" ixz="0" iyz="0"/></inertial>
    <visual><origin xyz="0 0 0" rpy="0 0 0"/>
      <geometry><sphere radius="0.05"/></geometry><material name="black"/></visual>
    <collision><origin xyz="0 0 0" rpy="0 0 0"/>
      <geometry><sphere radius="0.05"/></geometry></collision>
  </link>
  <joint name="fr_foot_joint" type="fixed">
    <parent link="fr_cannon_link"/><child link="fr_foot_link"/>
    <origin xyz="0 0 -0.18" rpy="0 0 0"/>
  </joint>
  <gazebo reference="fr_foot_link">
    <material>Gazebo/FlatBlack</material>
    <kp>1000000.0</kp><kd>200.0</kd>
    <mu1>2.0</mu1><mu2>2.0</mu2>
    <minDepth>0.005</minDepth>
  </gazebo>

  <!-- ── REAR-LEFT ── -->
  <link name="rl_hip_link">
    <inertial><mass value="4.0"/><origin xyz="0 0 0" rpy="0 0 0"/>
      <inertia ixx="0.012" iyy="0.012" izz="0.007" ixy="0" ixz="0" iyz="0"/></inertial>
    <visual><origin xyz="0 0 -0.06" rpy="0 0 0"/>
      <geometry><cylinder radius="0.05" length="0.12"/></geometry><material name="silver"/></visual>
    <collision><origin xyz="0 0 -0.05" rpy="0 0 0">
      </origin><geometry><cylinder radius="0.04" length="0.10"/></geometry></collision>
  </link>
  <joint name="rl_hip_joint" type="revolute">
    <parent link="base_link"/><child link="rl_hip_link"/>
    <origin xyz="-0.65 0.40 0.12" rpy="0 0 0"/>
    <axis xyz="0 0 1"/>
    <limit lower="-0.35" upper="0.35" effort="200" velocity="2.0"/>
    <dynamics damping="2.5" friction="0.3"/>
  </joint>
  <gazebo reference="rl_hip_link"><material>Gazebo/Grey</material></gazebo>
  <link name="rl_thigh_link">
    <inertial><mass value="5.0"/><origin xyz="0 0 -0.25" rpy="0 0 0"/>
      <inertia ixx="0.1068" iyy="0.1068" izz="0.0051" ixy="0" ixz="0" iyz="0"/></inertial>
    <visual><origin xyz="0 0 -0.25" rpy="0 0 0">
      </origin><geometry><cylinder radius="0.045" length="0.50"/></geometry><material name="orange"/></visual>
    <collision><origin xyz="0 0 -0.25" rpy="0 0 0">
      </origin><geometry><cylinder radius="0.045" length="0.50"/></geometry></collision>
  </link>
  <joint name="rl_thigh_joint" type="revolute">
    <parent link="rl_hip_link"/><child link="rl_thigh_link"/>
    <origin xyz="0 0 -0.10" rpy="0 0 0"/><axis xyz="0 1 0"/>
    <limit lower="-1.20" upper="0.30" effort="500" velocity="3.0"/>
    <dynamics damping="2.5" friction="0.3"/>
  </joint>
  <gazebo reference="rl_thigh_link"><material>Gazebo/Orange</material></gazebo>
  <link name="rl_shank_link">
    <inertial><mass value="4.0"/><origin xyz="0 0 -0.225" rpy="0 0 0"/>
      <inertia ixx="0.0695" iyy="0.0695" izz="0.0032" ixy="0" ixz="0" iyz="0"/></inertial>
    <visual><origin xyz="0 0 -0.225" rpy="0 0 0">
      </origin><geometry><cylinder radius="0.04" length="0.45"/></geometry><material name="dark_grey"/></visual>
    <collision><origin xyz="0 0 -0.225" rpy="0 0 0">
      </origin><geometry><cylinder radius="0.04" length="0.45"/></geometry></collision>
  </link>
  <joint name="rl_knee_joint" type="revolute">
    <parent link="rl_thigh_link"/><child link="rl_shank_link"/>
    <origin xyz="0 0 -0.50" rpy="0 0 0"/><axis xyz="0 1 0"/>
    <limit lower="0.10" upper="1.80" effort="800" velocity="5.0"/>
    <dynamics damping="3.5" friction="0.3"/>
  </joint>
  <gazebo reference="rl_shank_link"><material>Gazebo/DarkGrey</material></gazebo>
  <!-- Cannon bone (metatarsal/metacarpal): pantograph-kept near vertical -->
  <link name="rl_cannon_link">
    <inertial><mass value="1.2"/><origin xyz="0 0 -0.11" rpy="0 0 0"/>
      <inertia ixx="0.0049" iyy="0.0049" izz="0.0005" ixy="0" ixz="0" iyz="0"/></inertial>
    <visual><origin xyz="0 0 -0.11" rpy="0 0 0"/>
      <geometry><cylinder radius="0.03" length="0.22"/></geometry><material name="dark_grey"/></visual>
    <collision><origin xyz="0 0 -0.11" rpy="0 0 0"/>
      <geometry><cylinder radius="0.03" length="0.22"/></geometry></collision>
  </link>
  <joint name="rl_cannon_joint" type="revolute">
    <parent link="rl_shank_link"/><child link="rl_cannon_link"/>
    <origin xyz="0 0 -0.45" rpy="0 0 0"/><axis xyz="0 1 0"/>
    <limit lower="-2.0" upper="2.0" effort="100" velocity="6.0"/>
    <dynamics damping="1.0" friction="0.1"/>
  </joint>
  <gazebo reference="rl_cannon_link"><material>Gazebo/DarkGrey</material></gazebo>

    <link name="rl_foot_link">
    <inertial><mass value="0.5"/><origin xyz="0 0 0" rpy="0 0 0"/>
      <inertia ixx="0.00072" iyy="0.00072" izz="0.00072" ixy="0" ixz="0" iyz="0"/></inertial>
    <visual><origin xyz="0 0 0" rpy="0 0 0"/>
      <geometry><sphere radius="0.06"/></geometry><material name="black"/></visual>
    <collision><origin xyz="0 0 0" rpy="0 0 0"/>
      <geometry><sphere radius="0.06"/></geometry></collision>
  </link>
  <joint name="rl_foot_joint" type="fixed">
    <parent link="rl_cannon_link"/><child link="rl_foot_link"/>
    <origin xyz="0 0 -0.22" rpy="0 0 0"/>
  </joint>
  <gazebo reference="rl_foot_link">
    <material>Gazebo/FlatBlack</material>
    <kp>1000000.0</kp><kd>200.0</kd>
    <mu1>2.0</mu1><mu2>2.0</mu2>
    <minDepth>0.005</minDepth>
  </gazebo>

  <!-- ── REAR-RIGHT ── -->
  <link name="rr_hip_link">
    <inertial><mass value="4.0"/><origin xyz="0 0 0" rpy="0 0 0"/>
      <inertia ixx="0.012" iyy="0.012" izz="0.007" ixy="0" ixz="0" iyz="0"/></inertial>
    <visual><origin xyz="0 0 -0.06" rpy="0 0 0"/>
      <geometry><cylinder radius="0.05" length="0.12"/></geometry><material name="silver"/></visual>
    <collision><origin xyz="0 0 -0.05" rpy="0 0 0">
      </origin><geometry><cylinder radius="0.04" length="0.10"/></geometry></collision>
  </link>
  <joint name="rr_hip_joint" type="revolute">
    <parent link="base_link"/><child link="rr_hip_link"/>
    <origin xyz="-0.65 -0.40 0.12" rpy="0 0 0"/>
    <axis xyz="0 0 1"/>
    <limit lower="-0.35" upper="0.35" effort="200" velocity="2.0"/>
    <dynamics damping="2.5" friction="0.3"/>
  </joint>
  <gazebo reference="rr_hip_link"><material>Gazebo/Grey</material></gazebo>
  <link name="rr_thigh_link">
    <inertial><mass value="5.0"/><origin xyz="0 0 -0.25" rpy="0 0 0"/>
      <inertia ixx="0.1068" iyy="0.1068" izz="0.0051" ixy="0" ixz="0" iyz="0"/></inertial>
    <visual><origin xyz="0 0 -0.25" rpy="0 0 0">
      </origin><geometry><cylinder radius="0.045" length="0.50"/></geometry><material name="orange"/></visual>
    <collision><origin xyz="0 0 -0.25" rpy="0 0 0">
      </origin><geometry><cylinder radius="0.045" length="0.50"/></geometry></collision>
  </link>
  <joint name="rr_thigh_joint" type="revolute">
    <parent link="rr_hip_link"/><child link="rr_thigh_link"/>
    <origin xyz="0 0 -0.10" rpy="0 0 0"/><axis xyz="0 1 0"/>
    <limit lower="-1.20" upper="0.30" effort="500" velocity="3.0"/>
    <dynamics damping="2.5" friction="0.3"/>
  </joint>
  <gazebo reference="rr_thigh_link"><material>Gazebo/Orange</material></gazebo>
  <link name="rr_shank_link">
    <inertial><mass value="4.0"/><origin xyz="0 0 -0.225" rpy="0 0 0"/>
      <inertia ixx="0.0695" iyy="0.0695" izz="0.0032" ixy="0" ixz="0" iyz="0"/></inertial>
    <visual><origin xyz="0 0 -0.225" rpy="0 0 0">
      </origin><geometry><cylinder radius="0.04" length="0.45"/></geometry><material name="dark_grey"/></visual>
    <collision><origin xyz="0 0 -0.225" rpy="0 0 0">
      </origin><geometry><cylinder radius="0.04" length="0.45"/></geometry></collision>
  </link>
  <joint name="rr_knee_joint" type="revolute">
    <parent link="rr_thigh_link"/><child link="rr_shank_link"/>
    <origin xyz="0 0 -0.50" rpy="0 0 0"/><axis xyz="0 1 0"/>
    <limit lower="0.10" upper="1.80" effort="800" velocity="5.0"/>
    <dynamics damping="3.5" friction="0.3"/>
  </joint>
  <gazebo reference="rr_shank_link"><material>Gazebo/DarkGrey</material></gazebo>
  <!-- Cannon bone (metatarsal/metacarpal): pantograph-kept near vertical -->
  <link name="rr_cannon_link">
    <inertial><mass value="1.2"/><origin xyz="0 0 -0.11" rpy="0 0 0"/>
      <inertia ixx="0.0049" iyy="0.0049" izz="0.0005" ixy="0" ixz="0" iyz="0"/></inertial>
    <visual><origin xyz="0 0 -0.11" rpy="0 0 0"/>
      <geometry><cylinder radius="0.03" length="0.22"/></geometry><material name="dark_grey"/></visual>
    <collision><origin xyz="0 0 -0.11" rpy="0 0 0"/>
      <geometry><cylinder radius="0.03" length="0.22"/></geometry></collision>
  </link>
  <joint name="rr_cannon_joint" type="revolute">
    <parent link="rr_shank_link"/><child link="rr_cannon_link"/>
    <origin xyz="0 0 -0.45" rpy="0 0 0"/><axis xyz="0 1 0"/>
    <limit lower="-2.0" upper="2.0" effort="100" velocity="6.0"/>
    <dynamics damping="1.0" friction="0.1"/>
  </joint>
  <gazebo reference="rr_cannon_link"><material>Gazebo/DarkGrey</material></gazebo>

    <link name="rr_foot_link">
    <inertial><mass value="0.5"/><origin xyz="0 0 0" rpy="0 0 0"/>
      <inertia ixx="0.00072" iyy="0.00072" izz="0.00072" ixy="0" ixz="0" iyz="0"/></inertial>
    <visual><origin xyz="0 0 0" rpy="0 0 0"/>
      <geometry><sphere radius="0.06"/></geometry><material name="black"/></visual>
    <collision><origin xyz="0 0 0" rpy="0 0 0"/>
      <geometry><sphere radius="0.06"/></geometry></collision>
  </link>
  <joint name="rr_foot_joint" type="fixed">
    <parent link="rr_cannon_link"/><child link="rr_foot_link"/>
    <origin xyz="0 0 -0.22" rpy="0 0 0"/>
  </joint>
  <gazebo reference="rr_foot_link">
    <material>Gazebo/FlatBlack</material>
    <kp>1000000.0</kp><kd>200.0</kd>
    <mu1>2.0</mu1><mu2>2.0</mu2>
    <minDepth>0.005</minDepth>
  </gazebo>

  <!-- ═══════════════════════════════════════════════════════
       CARRIAGE — vis-à-vis style, hitched to bovine robot
       Robot faces -X, carriage trails at +X side.
       Kinematic chain:
         base_link → cow_hitch_pitch (revolute, y, ±0.35 rad)
           → shaft_link (U-fork, 2.35m, bars at ±0.50m to clear body)
             → perch_pitch (revolute, y, at perch)
               → front_assembly_link (perch + front axle + turntable)
                 ├─ cart_fl_wheel_joint (continuous)
                 ├─ cart_fr_wheel_joint (continuous)
                 └─ turntable_yaw_joint (revolute, z, ±45°)
                    → cart_body_link (body, driver, etc.)
                      → rear_axle_joint (fixed)
                        → rear_axle_link
                          ├─ cart_rl_wheel_joint (continuous)
                          └─ cart_rr_wheel_joint (continuous)
       Cow-side hitch: pitch only (Y-axis) — shaft pivots up/down
       Perch-side hitch: pitch (Y-axis) — same as real carriage hitch
       Total: 2 pitch DOF + turntable yaw = 3 DOF
       Shaft bars at ±0.50m (1.0m apart) clear 0.88m body width
       Real measurements from owner's carriage:
         Front wheels ⌀ 85 cm,  Rear wheels ⌀ 105 cm
         Wheelbase 205 cm,  Track 145 cm
         Shaft 235 cm long, U-shaped
         Perch: shaft connects to front axle assembly 50cm fwd of wheel center
         Body: 250 × 110 × 110 cm, ~60 cm off ground
         Driver: ~85 kg on front bench
       Total carriage mass ≈ 105 kg + 85 kg driver = 190 kg
  ═══════════════════════════════════════════════════════ -->

  <!-- Cow-side hitch — pitch only (up/down in forward direction)
       Like a real carriage hitch pivot: shaft can tilt up/down but
       does not yaw or roll relative to the cow body. -->
  <joint name="cow_hitch_pitch_joint" type="revolute">
    <parent link="base_link"/><child link="shaft_link"/>
    <origin xyz="0.0 0 -0.30" rpy="0 0 0"/>
    <axis xyz="0 1 0"/>
    <limit lower="-0.35" upper="0.35" effort="0" velocity="2.0"/>
    <dynamics damping="1.0" friction="0.1"/>
  </joint>

  <!-- Shaft — U-shaped wooden fork, 2.35m long, extending in +X (behind robot)
       Bars at ±0.50m (1.0m apart) to clear 0.88m body width -->
  <link name="shaft_link">
    <inertial><mass value="15.0"/><origin xyz="1.175 0 0" rpy="0 0 0"/>
      <inertia ixx="0.15" iyy="6.93" izz="7.00" ixy="0" ixz="0" iyz="0"/></inertial>
    <!-- Left shaft bar -->
    <visual><origin xyz="1.175 0.50 0" rpy="0 0 0"/>
      <geometry><box size="2.35 0.05 0.05"/></geometry><material name="wood"/></visual>
    <collision><origin xyz="1.175 0.50 0" rpy="0 0 0"/>
      <geometry><box size="2.35 0.05 0.05"/></geometry></collision>
    <!-- Right shaft bar -->
    <visual><origin xyz="1.175 -0.50 0" rpy="0 0 0"/>
      <geometry><box size="2.35 0.05 0.05"/></geometry><material name="wood"/></visual>
    <collision><origin xyz="1.175 -0.50 0" rpy="0 0 0"/>
      <geometry><box size="2.35 0.05 0.05"/></geometry></collision>
    <!-- Cross piece at carriage end (tapers to ~0.85m) -->
    <visual><origin xyz="2.30 0 0" rpy="0 0 0"/>
      <geometry><box size="0.05 0.85 0.05"/></geometry><material name="wood"/></visual>
    <collision><origin xyz="2.30 0 0" rpy="0 0 0"/>
      <geometry><box size="0.05 0.85 0.05"/></geometry></collision>
  </link>

  <!-- Perch pitch joint — pivot at front of front axle assembly
       Moderate damping: allows free pitch motion over bumps without oscillation. -->
  <joint name="perch_pitch_joint" type="revolute">
    <parent link="shaft_link"/><child link="front_assembly_link"/>
    <origin xyz="2.35 0 0.015" rpy="0 0 0"/>
    <axis xyz="0 1 0"/>
    <limit lower="-0.35" upper="0.35" effort="0" velocity="2.0"/>
    <dynamics damping="1.5" friction="0.2"/>
  </joint>

  <!-- Front assembly (perch beam + front axle + turntable pin) ~8 kg -->
  <link name="front_assembly_link">
    <inertial><mass value="8.0"/><origin xyz="0.25 0 -0.15" rpy="0 0 0"/>
      <inertia ixx="0.20" iyy="0.10" izz="0.25" ixy="0" ixz="0" iyz="0"/></inertial>
    <!-- Perch beam (shaft-to-axle connection) -->
    <visual><origin xyz="0.25 0 0" rpy="0 0 0"/>
      <geometry><box size="0.50 0.08 0.08"/></geometry><material name="iron"/></visual>
    <collision><origin xyz="0.25 0 0" rpy="0 0 0"/>
      <geometry><box size="0.50 0.08 0.08"/></geometry></collision>
    <!-- Front axle bar -->
    <visual><origin xyz="0.50 0 -0.37" rpy="0 0 0"/>
      <geometry><box size="0.06 1.40 0.06"/></geometry><material name="iron"/></visual>
    <collision><origin xyz="0.50 0 -0.37" rpy="0 0 0"/>
      <geometry><box size="0.06 1.40 0.06"/></geometry></collision>
    <!-- Turntable circle (fifth-wheel plate) -->
    <visual><origin xyz="0.50 0 -0.02" rpy="0 0 0"/>
      <geometry><cylinder radius="0.15" length="0.04"/></geometry><material name="iron"/></visual>
    <collision><origin xyz="0.50 0 -0.02" rpy="0 0 0"/>
      <geometry><cylinder radius="0.15" length="0.04"/></geometry></collision>
  </link>

  <!-- ── Front-Left Wheel (⌀85cm) — on front assembly ── -->
  <joint name="cart_fl_wheel_joint" type="continuous">
    <parent link="front_assembly_link"/><child link="cart_fl_wheel_link"/>
    <origin xyz="0.50 0.725 -0.37" rpy="0 0 0"/>
    <axis xyz="0 1 0"/>
    <dynamics damping="0.5" friction="0.1"/>
  </joint>
  <link name="cart_fl_wheel_link">
    <inertial><mass value="4.0"/><origin xyz="0 0 0" rpy="0 0 0"/>
      <inertia ixx="0.091" iyy="0.181" izz="0.091" ixy="0" ixz="0" iyz="0"/></inertial>
    <visual><origin xyz="0 0 0" rpy="1.5708 0 0"/>
      <geometry><cylinder radius="0.425" length="0.05"/></geometry><material name="wood"/></visual>
    <collision><origin xyz="0 0 0" rpy="1.5708 0 0"/>
      <geometry><cylinder radius="0.425" length="0.05"/></geometry></collision>
    <!-- Wheel hub -->
    <visual><origin xyz="0 0.03 0" rpy="1.5708 0 0"/>
      <geometry><cylinder radius="0.06" length="0.08"/></geometry><material name="iron"/></visual>
  </link>

  <!-- ── Front-Right Wheel (⌀85cm) — on front assembly ── -->
  <joint name="cart_fr_wheel_joint" type="continuous">
    <parent link="front_assembly_link"/><child link="cart_fr_wheel_link"/>
    <origin xyz="0.50 -0.725 -0.37" rpy="0 0 0"/>
    <axis xyz="0 1 0"/>
    <dynamics damping="0.5" friction="0.1"/>
  </joint>
  <link name="cart_fr_wheel_link">
    <inertial><mass value="4.0"/><origin xyz="0 0 0" rpy="0 0 0"/>
      <inertia ixx="0.091" iyy="0.181" izz="0.091" ixy="0" ixz="0" iyz="0"/></inertial>
    <visual><origin xyz="0 0 0" rpy="1.5708 0 0"/>
      <geometry><cylinder radius="0.425" length="0.05"/></geometry><material name="wood"/></visual>
    <collision><origin xyz="0 0 0" rpy="1.5708 0 0"/>
      <geometry><cylinder radius="0.425" length="0.05"/></geometry></collision>
    <visual><origin xyz="0 -0.03 0" rpy="1.5708 0 0"/>
      <geometry><cylinder radius="0.06" length="0.08"/></geometry><material name="iron"/></visual>
  </link>

  <!-- Turntable yaw joint — cart body rotates relative to front axle assembly
       Moderate damping: enough to prevent oscillation but allows smooth turning.
       The cart body's inertia (140 kg) provides natural stability. -->
  <joint name="turntable_yaw_joint" type="revolute">
    <parent link="front_assembly_link"/><child link="cart_body_link"/>
    <origin xyz="0.50 0 0" rpy="0 0 0"/>
    <axis xyz="0 0 1"/>
    <limit lower="-0.785" upper="0.785" effort="0" velocity="2.0"/>
    <dynamics damping="4.0" friction="0.3"/>
  </joint>

  <!-- Cart body — 250×110×110 cm wooden carriage body
       Origin at turntable center (directly above front wheel center)
       Visuals shifted down so body floor sits at ~60cm off ground
       (turntable origin at z≈0.795m abs → floor at -0.195 rel = 0.60m abs)
       Driver (85 kg) seated on front bench -->
  <link name="cart_body_link">
    <!-- Combined inertia: carriage structure 55 kg + driver 85 kg = 140 kg
         COM shifted down to match lowered body position -->
    <inertial><mass value="140.0"/><origin xyz="0.90 0 0.07" rpy="0 0 0"/>
      <inertia ixx="25.0" iyy="95.0" izz="85.0" ixy="0" ixz="0" iyz="0"/></inertial>

    <!-- Main body floor/deck — abs z ≈ 0.60m -->
    <visual><origin xyz="1.025 0 -0.195" rpy="0 0 0"/>
      <geometry><box size="2.50 1.10 0.06"/></geometry><material name="wood"/></visual>
    <collision><origin xyz="1.025 0 -0.195" rpy="0 0 0"/>
      <geometry><box size="2.50 1.10 0.06"/></geometry></collision>

    <!-- Left side panel -->
    <visual><origin xyz="1.025 0.52 0.195" rpy="0 0 0"/>
      <geometry><box size="2.20 0.06 0.72"/></geometry><material name="wood"/></visual>
    <collision><origin xyz="1.025 0.52 0.195" rpy="0 0 0"/>
      <geometry><box size="2.20 0.06 0.72"/></geometry></collision>

    <!-- Right side panel -->
    <visual><origin xyz="1.025 -0.52 0.195" rpy="0 0 0"/>
      <geometry><box size="2.20 0.06 0.72"/></geometry><material name="wood"/></visual>
    <collision><origin xyz="1.025 -0.52 0.195" rpy="0 0 0"/>
      <geometry><box size="2.20 0.06 0.72"/></geometry></collision>

    <!-- Front panel (cow side, kick board) -->
    <visual><origin xyz="-0.05 0 0.145" rpy="0 0 0"/>
      <geometry><box size="0.06 1.00 0.62"/></geometry><material name="dark_grey"/></visual>

    <!-- Rear panel -->
    <visual><origin xyz="2.10 0 0.145" rpy="0 0 0"/>
      <geometry><box size="0.06 1.00 0.62"/></geometry><material name="dark_grey"/></visual>

    <!-- Center divider panel -->
    <visual><origin xyz="1.025 0 0.145" rpy="0 0 0"/>
      <geometry><box size="0.06 0.90 0.50"/></geometry><material name="dark_grey"/></visual>

    <!-- Front bench seat (driver side, closest to cow) -->
    <visual><origin xyz="0.30 0 0.105" rpy="0 0 0"/>
      <geometry><box size="0.45 0.90 0.08"/></geometry><material name="red_velvet"/></visual>
    <!-- Front seat backrest -->
    <visual><origin xyz="0.08 0 0.325" rpy="0 0 0"/>
      <geometry><box size="0.06 0.90 0.36"/></geometry><material name="wood"/></visual>

    <!-- Rear bench seat -->
    <visual><origin xyz="1.75 0 0.105" rpy="0 0 0"/>
      <geometry><box size="0.45 0.90 0.08"/></geometry><material name="red_velvet"/></visual>
    <!-- Rear seat backrest -->
    <visual><origin xyz="1.97 0 0.325" rpy="0 0 0"/>
      <geometry><box size="0.06 0.90 0.36"/></geometry><material name="wood"/></visual>

    <!-- Driver figure (85 kg, seated on front bench) -->
    <!-- Torso -->
    <visual><origin xyz="0.30 0 0.465" rpy="0 0 0"/>
      <geometry><box size="0.30 0.40 0.55"/></geometry><material name="dark_grey"/></visual>
    <!-- Head -->
    <visual><origin xyz="0.30 0 0.815" rpy="0 0 0"/>
      <geometry><sphere radius="0.12"/></geometry><material name="light_grey"/></visual>

    <!-- Left mudguard / fender (over rear wheels) -->
    <visual><origin xyz="1.85 0.58 -0.245" rpy="0 0 0"/>
      <geometry><box size="0.70 0.12 0.06"/></geometry><material name="wood"/></visual>
    <!-- Right mudguard -->
    <visual><origin xyz="1.85 -0.58 -0.245" rpy="0 0 0"/>
      <geometry><box size="0.70 0.12 0.06"/></geometry><material name="wood"/></visual>

    <!-- Iron underframe / chassis rail (left) -->
    <visual><origin xyz="1.025 0.40 -0.405" rpy="0 0 0"/>
      <geometry><box size="2.60 0.04 0.04"/></geometry><material name="iron"/></visual>
    <!-- Iron underframe / chassis rail (right) -->
    <visual><origin xyz="1.025 -0.40 -0.405" rpy="0 0 0"/>
      <geometry><box size="2.60 0.04 0.04"/></geometry><material name="iron"/></visual>

    <!-- Left carriage lamp bracket -->
    <visual><origin xyz="-0.15 0.50 0.595" rpy="0 0 0"/>
      <geometry><cylinder radius="0.02" length="0.25"/></geometry><material name="iron"/></visual>
    <!-- Left lamp housing -->
    <visual><origin xyz="-0.15 0.54 0.745" rpy="0 0 0"/>
      <geometry><box size="0.10 0.10 0.15"/></geometry><material name="iron"/></visual>
    <!-- Right carriage lamp bracket -->
    <visual><origin xyz="-0.15 -0.50 0.595" rpy="0 0 0"/>
      <geometry><cylinder radius="0.02" length="0.25"/></geometry><material name="iron"/></visual>
    <!-- Right lamp housing -->
    <visual><origin xyz="-0.15 -0.54 0.745" rpy="0 0 0"/>
      <geometry><box size="0.10 0.10 0.15"/></geometry><material name="iron"/></visual>

    <!-- Folding hood frame (rear, collapsed) -->
    <visual><origin xyz="2.05 0 0.645" rpy="0 0 0"/>
      <geometry><box size="0.08 0.95 0.15"/></geometry><material name="wood"/></visual>
  </link>

  <!-- ── Rear axle (fixed to cart body) ── -->
  <joint name="rear_axle_joint" type="fixed">
    <parent link="cart_body_link"/><child link="rear_axle_link"/>
    <origin xyz="2.05 0 -0.27" rpy="0 0 0"/>
  </joint>
  <link name="rear_axle_link">
    <inertial><mass value="6.0"/><origin xyz="0 0 0" rpy="0 0 0"/>
      <inertia ixx="0.53" iyy="0.003" izz="0.53" ixy="0" ixz="0" iyz="0"/></inertial>
    <visual><origin xyz="0 0 0" rpy="0 0 0"/>
      <geometry><box size="0.06 1.40 0.06"/></geometry><material name="iron"/></visual>
    <collision><origin xyz="0 0 0" rpy="0 0 0"/>
      <geometry><box size="0.06 1.40 0.06"/></geometry></collision>
  </link>

  <!-- ── Rear-Left Wheel (⌀105cm) ── -->
  <joint name="cart_rl_wheel_joint" type="continuous">
    <parent link="rear_axle_link"/><child link="cart_rl_wheel_link"/>
    <origin xyz="0 0.725 0" rpy="0 0 0"/>
    <axis xyz="0 1 0"/>
    <dynamics damping="0.5" friction="0.1"/>
  </joint>
  <link name="cart_rl_wheel_link">
    <inertial><mass value="5.0"/><origin xyz="0 0 0" rpy="0 0 0"/>
      <inertia ixx="0.174" iyy="0.345" izz="0.174" ixy="0" ixz="0" iyz="0"/></inertial>
    <visual><origin xyz="0 0 0" rpy="1.5708 0 0"/>
      <geometry><cylinder radius="0.525" length="0.06"/></geometry><material name="wood"/></visual>
    <collision><origin xyz="0 0 0" rpy="1.5708 0 0"/>
      <geometry><cylinder radius="0.525" length="0.06"/></geometry></collision>
    <visual><origin xyz="0 0.04 0" rpy="1.5708 0 0"/>
      <geometry><cylinder radius="0.06" length="0.10"/></geometry><material name="iron"/></visual>
  </link>

  <!-- ── Rear-Right Wheel (⌀105cm) ── -->
  <joint name="cart_rr_wheel_joint" type="continuous">
    <parent link="rear_axle_link"/><child link="cart_rr_wheel_link"/>
    <origin xyz="0 -0.725 0" rpy="0 0 0"/>
    <axis xyz="0 1 0"/>
    <dynamics damping="0.5" friction="0.1"/>
  </joint>
  <link name="cart_rr_wheel_link">
    <inertial><mass value="5.0"/><origin xyz="0 0 0" rpy="0 0 0"/>
      <inertia ixx="0.174" iyy="0.345" izz="0.174" ixy="0" ixz="0" iyz="0"/></inertial>
    <visual><origin xyz="0 0 0" rpy="1.5708 0 0"/>
      <geometry><cylinder radius="0.525" length="0.06"/></geometry><material name="wood"/></visual>
    <collision><origin xyz="0 0 0" rpy="1.5708 0 0"/>
      <geometry><cylinder radius="0.525" length="0.06"/></geometry></collision>
    <visual><origin xyz="0 -0.04 0" rpy="1.5708 0 0"/>
      <geometry><cylinder radius="0.06" length="0.10"/></geometry><material name="iron"/></visual>
  </link>

  <!-- ── Gazebo contact/material for carriage ── -->
  <gazebo reference="shaft_link"><material>Gazebo/Wood</material></gazebo>
  <gazebo reference="front_assembly_link"><material>Gazebo/Grey</material></gazebo>
  <gazebo reference="cart_body_link"><material>Gazebo/Wood</material></gazebo>
  <gazebo reference="rear_axle_link"><material>Gazebo/Grey</material></gazebo>

  <gazebo reference="cart_fl_wheel_link">
    <material>Gazebo/Wood</material>
    <kp>1000000.0</kp><kd>100.0</kd>
    <mu1>1.0</mu1><mu2>1.0</mu2>
    <minDepth>0.003</minDepth>
  </gazebo>
  <gazebo reference="cart_fr_wheel_link">
    <material>Gazebo/Wood</material>
    <kp>1000000.0</kp><kd>100.0</kd>
    <mu1>1.0</mu1><mu2>1.0</mu2>
    <minDepth>0.003</minDepth>
  </gazebo>
  <gazebo reference="cart_rl_wheel_link">
    <material>Gazebo/Wood</material>
    <kp>1000000.0</kp><kd>100.0</kd>
    <mu1>1.0</mu1><mu2>1.0</mu2>
    <minDepth>0.003</minDepth>
  </gazebo>
  <gazebo reference="cart_rr_wheel_link">
    <material>Gazebo/Wood</material>
    <kp>1000000.0</kp><kd>100.0</kd>
    <mu1>1.0</mu1><mu2>1.0</mu2>
    <minDepth>0.003</minDepth>
  </gazebo>

  <!-- ═══════════════════════════════════════════════════════
       ROS2 CONTROL — hardware interface
       17 commanded joints: spine(Z) + 4x hip(Z) + 4x thigh(Y) + 4x knee(Y) + 4x cannon(Y)
       Carriage wheels are passive — not included in ros2_control.
  ═══════════════════════════════════════════════════════ -->

  <ros2_control name="GazeboSystem" type="system">
    <hardware>
      <plugin>gz_ros2_control/GazeboSimSystem</plugin>
    </hardware>

    <!-- Spine yaw — articulated spine for turning -->
    <joint name="spine_yaw_joint">
      <command_interface name="position">
        <param name="min">-0.30</param><param name="max">0.30</param>
      </command_interface>
      <state_interface name="position">
        <param name="initial_value">0.0</param>
      </state_interface>
      <state_interface name="velocity"/>
      <state_interface name="effort"/>
    </joint>

    <!-- Front-left -->
    <joint name="fl_hip_joint">
      <command_interface name="position">
        <param name="min">-0.35</param><param name="max">0.35</param>
      </command_interface>
      <state_interface name="position">
        <param name="initial_value">0.0</param>
      </state_interface>
      <state_interface name="velocity"/>
      <state_interface name="effort"/>
    </joint>
    <joint name="fl_thigh_joint">
      <command_interface name="position">
        <param name="min">-0.30</param><param name="max">1.20</param>
      </command_interface>
      <state_interface name="position">
        <param name="initial_value">0.55</param>
      </state_interface>
      <state_interface name="velocity"/>
      <state_interface name="effort"/>
    </joint>
    <joint name="fl_knee_joint">
      <command_interface name="position">
        <param name="min">-1.80</param><param name="max">-0.10</param>
      </command_interface>
      <state_interface name="position">
        <param name="initial_value">-1.10</param>
      </state_interface>
      <state_interface name="velocity"/>
      <state_interface name="effort"/>
    </joint>
    <joint name="fl_cannon_joint">
      <command_interface name="position">
        <param name="min">-2.0</param><param name="max">2.0</param>
      </command_interface>
      <state_interface name="position">
        <param name="initial_value">0.63</param>
      </state_interface>
      <state_interface name="velocity"/>
      <state_interface name="effort"/>
    </joint>

    <!-- Front-right -->
    <joint name="fr_hip_joint">
      <command_interface name="position">
        <param name="min">-0.35</param><param name="max">0.35</param>
      </command_interface>
      <state_interface name="position">
        <param name="initial_value">0.0</param>
      </state_interface>
      <state_interface name="velocity"/>
      <state_interface name="effort"/>
    </joint>
    <joint name="fr_thigh_joint">
      <command_interface name="position">
        <param name="min">-0.30</param><param name="max">1.20</param>
      </command_interface>
      <state_interface name="position">
        <param name="initial_value">0.55</param>
      </state_interface>
      <state_interface name="velocity"/>
      <state_interface name="effort"/>
    </joint>
    <joint name="fr_knee_joint">
      <command_interface name="position">
        <param name="min">-1.80</param><param name="max">-0.10</param>
      </command_interface>
      <state_interface name="position">
        <param name="initial_value">-1.10</param>
      </state_interface>
      <state_interface name="velocity"/>
      <state_interface name="effort"/>
    </joint>
    <joint name="fr_cannon_joint">
      <command_interface name="position">
        <param name="min">-2.0</param><param name="max">2.0</param>
      </command_interface>
      <state_interface name="position">
        <param name="initial_value">0.63</param>
      </state_interface>
      <state_interface name="velocity"/>
      <state_interface name="effort"/>
    </joint>

    <!-- Rear-left -->
    <joint name="rl_hip_joint">
      <command_interface name="position">
        <param name="min">-0.35</param><param name="max">0.35</param>
      </command_interface>
      <state_interface name="position">
        <param name="initial_value">0.0</param>
      </state_interface>
      <state_interface name="velocity"/>
      <state_interface name="effort"/>
    </joint>
    <joint name="rl_thigh_joint">
      <command_interface name="position">
        <param name="min">-1.20</param><param name="max">0.30</param>
      </command_interface>
      <state_interface name="position">
        <param name="initial_value">-0.55</param>
      </state_interface>
      <state_interface name="velocity"/>
      <state_interface name="effort"/>
    </joint>
    <joint name="rl_knee_joint">
      <command_interface name="position">
        <param name="min">0.10</param><param name="max">1.80</param>
      </command_interface>
      <state_interface name="position">
        <param name="initial_value">1.10</param>
      </state_interface>
      <state_interface name="velocity"/>
      <state_interface name="effort"/>
    </joint>
    <joint name="rl_cannon_joint">
      <command_interface name="position">
        <param name="min">-2.0</param><param name="max">2.0</param>
      </command_interface>
      <state_interface name="position">
        <param name="initial_value">-0.47</param>
      </state_interface>
      <state_interface name="velocity"/>
      <state_interface name="effort"/>
    </joint>

    <!-- Rear-right -->
    <joint name="rr_hip_joint">
      <command_interface name="position">
        <param name="min">-0.35</param><param name="max">0.35</param>
      </command_interface>
      <state_interface name="position">
        <param name="initial_value">0.0</param>
      </state_interface>
      <state_interface name="velocity"/>
      <state_interface name="effort"/>
    </joint>
    <joint name="rr_thigh_joint">
      <command_interface name="position">
        <param name="min">-1.20</param><param name="max">0.30</param>
      </command_interface>
      <state_interface name="position">
        <param name="initial_value">-0.55</param>
      </state_interface>
      <state_interface name="velocity"/>
      <state_interface name="effort"/>
    </joint>
    <joint name="rr_knee_joint">
      <command_interface name="position">
        <param name="min">0.10</param><param name="max">1.80</param>
      </command_interface>
      <state_interface name="position">
        <param name="initial_value">1.10</param>
      </state_interface>
      <state_interface name="velocity"/>
      <state_interface name="effort"/>
    </joint>
    <joint name="rr_cannon_joint">
      <command_interface name="position">
        <param name="min">-2.0</param><param name="max">2.0</param>
      </command_interface>
      <state_interface name="position">
        <param name="initial_value">-0.47</param>
      </state_interface>
      <state_interface name="velocity"/>
      <state_interface name="effort"/>
    </joint>
  </ros2_control>

  <!-- ═══════════════════════════════════════════════════════
       GAZEBO PLUGIN — loads gazebo_ros2_control
  ═══════════════════════════════════════════════════════ -->
  <gazebo>
    <plugin filename="gz_ros2_control-system" name="gz_ros2_control::GazeboSimROS2ControlPlugin">
      <parameters>$(find robotic_horse_control)/config/ros2_control.yaml</parameters>
    </plugin>
  </gazebo>

</robot>
