<?xml version="1.0"?>
<!--
  Robotic Horse - Quadruped with linear ballscrew knee joints
  
  Leg layout (top view):
      FL ---- FR
      |        |
      RL ---- RR
  
  Each leg:
    hip_link  → thigh (revolute hip joint, sagittal plane)
    thigh     → shank (revolute knee joint, driven by ballscrew actuator)
    shank     → foot  (fixed)
  
  The ballscrew linear actuator is modelled as a prismatic joint
  (actuator_link) that geometrically drives the knee revolute joint
  via a slider-crank relationship (see leg_kinematics.py).
  In PyBullet we directly control the knee revolute joint; force
  conversion is done in force_calculator.py.
  
  Body dimensions (metres):
    Length: 0.80   Width: 0.40   Height: 0.10
  Leg segment lengths:
    Thigh: 0.45    Shank: 0.50
  Hip offsets from body centre:
    X ± 0.35 (front/rear)   Y ± 0.18 (left/right)
-->
<robot name="robotic_horse">

  <!-- ════════════════════════════════════════════════════════════
       MATERIALS
  ════════════════════════════════════════════════════════════ -->
  <material name="dark_grey">
    <color rgba="0.2 0.2 0.2 1"/>
  </material>
  <material name="orange">
    <color rgba="0.9 0.4 0.0 1"/>
  </material>
  <material name="light_grey">
    <color rgba="0.7 0.7 0.7 1"/>
  </material>

  <!-- ════════════════════════════════════════════════════════════
       BASE / BODY
  ════════════════════════════════════════════════════════════ -->
  <link name="base_link">
    <inertial>
      <mass value="20.0"/>
      <origin xyz="0 0 0" rpy="0 0 0"/>
      <!-- Box inertia: m*(h²+d²)/12 etc. for 0.80×0.40×0.10 box -->
      <inertia ixx="0.138" iyy="1.075" izz="1.140" ixy="0" ixz="0" iyz="0"/>
    </inertial>
    <visual>
      <origin xyz="0 0 0" rpy="0 0 0"/>
      <geometry><box size="0.80 0.40 0.10"/></geometry>
      <material name="dark_grey"/>
    </visual>
    <collision>
      <origin xyz="0 0 0" rpy="0 0 0"/>
      <geometry><box size="0.80 0.40 0.10"/></geometry>
    </collision>
  </link>

  <!-- ════════════════════════════════════════════════════════════
       LEG MACRO  (repeated for FL, FR, RL, RR)
       Naming convention: {prefix} ∈ {fl, fr, rl, rr}
  ════════════════════════════════════════════════════════════ -->

  <!-- ── FRONT-LEFT ── -->
  <!-- Hip bracket (massless structural link) -->
  <link name="fl_hip_link">
    <inertial>
      <mass value="0.5"/>
      <origin xyz="0 0 0" rpy="0 0 0"/>
      <inertia ixx="0.001" iyy="0.001" izz="0.001" ixy="0" ixz="0" iyz="0"/>
    </inertial>
    <visual>
      <origin xyz="0 0 -0.04" rpy="0 0 0"/>
      <geometry><cylinder radius="0.03" length="0.08"/></geometry>
      <material name="light_grey"/>
    </visual>
    <collision>
      <origin xyz="0 0 -0.04" rpy="0 0 0"/>
      <geometry><cylinder radius="0.03" length="0.08"/></geometry>
    </collision>
  </link>

  <joint name="fl_hip_joint" type="revolute">
    <!-- Hip flexion/extension (pitches leg fore/aft) -->
    <parent link="base_link"/>
    <child link="fl_hip_link"/>
    <origin xyz="0.35 0.18 -0.05" rpy="0 0 0"/>
    <axis xyz="0 1 0"/>
    <limit lower="-0.6" upper="0.6" effort="300" velocity="3.0"/>
    <dynamics damping="0.5" friction="0.1"/>
  </joint>

  <link name="fl_thigh_link">
    <inertial>
      <mass value="1.5"/>
      <origin xyz="0 0 -0.225" rpy="0 0 0"/>
      <inertia ixx="0.025" iyy="0.025" izz="0.002" ixy="0" ixz="0" iyz="0"/>
    </inertial>
    <visual>
      <origin xyz="0 0 -0.225" rpy="0 0 0"/>
      <geometry><box size="0.04 0.04 0.45"/></geometry>
      <material name="orange"/>
    </visual>
    <collision>
      <origin xyz="0 0 -0.225" rpy="0 0 0"/>
      <geometry><box size="0.04 0.04 0.45"/></geometry>
    </collision>
  </link>

  <joint name="fl_thigh_joint" type="revolute">
    <parent link="fl_hip_link"/>
    <child link="fl_thigh_link"/>
    <origin xyz="0 0 -0.08" rpy="0 0 0"/>
    <axis xyz="0 1 0"/>
    <limit lower="-0.1" upper="1.2" effort="500" velocity="3.0"/>
    <dynamics damping="0.5" friction="0.1"/>
  </joint>

  <link name="fl_shank_link">
    <inertial>
      <mass value="1.0"/>
      <origin xyz="0 0 -0.25" rpy="0 0 0"/>
      <inertia ixx="0.021" iyy="0.021" izz="0.001" ixy="0" ixz="0" iyz="0"/>
    </inertial>
    <visual>
      <origin xyz="0 0 -0.25" rpy="0 0 0"/>
      <geometry><box size="0.03 0.03 0.50"/></geometry>
      <material name="dark_grey"/>
    </visual>
    <collision>
      <origin xyz="0 0 -0.25" rpy="0 0 0"/>
      <geometry><box size="0.03 0.03 0.50"/></geometry>
    </collision>
  </link>

  <!-- Knee joint – driven by ballscrew in real hardware -->
  <joint name="fl_knee_joint" type="revolute">
    <parent link="fl_thigh_link"/>
    <child link="fl_shank_link"/>
    <origin xyz="0 0 -0.45" rpy="0 0 0"/>
    <axis xyz="0 1 0"/>
    <limit lower="-2.0" upper="0.0" effort="800" velocity="5.0"/>
    <dynamics damping="0.8" friction="0.1"/>
  </joint>

  <link name="fl_foot_link">
    <inertial>
      <mass value="0.2"/>
      <origin xyz="0 0 0" rpy="0 0 0"/>
      <inertia ixx="0.0001" iyy="0.0001" izz="0.0001" ixy="0" ixz="0" iyz="0"/>
    </inertial>
    <visual>
      <origin xyz="0 0 0" rpy="0 0 0"/>
      <geometry><sphere radius="0.04"/></geometry>
      <material name="light_grey"/>
    </visual>
    <collision>
      <origin xyz="0 0 0" rpy="0 0 0"/>
      <geometry><sphere radius="0.04"/></geometry>
    </collision>
  </link>

  <joint name="fl_foot_joint" type="fixed">
    <parent link="fl_shank_link"/>
    <child link="fl_foot_link"/>
    <origin xyz="0 0 -0.50" rpy="0 0 0"/>
  </joint>

  <!-- ── FRONT-RIGHT ── -->
  <link name="fr_hip_link">
    <inertial><mass value="0.5"/><origin xyz="0 0 0" rpy="0 0 0"/>
      <inertia ixx="0.001" iyy="0.001" izz="0.001" ixy="0" ixz="0" iyz="0"/></inertial>
    <visual><origin xyz="0 0 -0.04" rpy="0 0 0"/>
      <geometry><cylinder radius="0.03" length="0.08"/></geometry><material name="light_grey"/></visual>
    <collision><origin xyz="0 0 -0.04" rpy="0 0 0"/>
      <geometry><cylinder radius="0.03" length="0.08"/></geometry></collision>
  </link>
  <joint name="fr_hip_joint" type="revolute">
    <parent link="base_link"/><child link="fr_hip_link"/>
    <origin xyz="0.35 -0.18 -0.05" rpy="0 0 0"/><axis xyz="0 1 0"/>
    <limit lower="-0.6" upper="0.6" effort="300" velocity="3.0"/>
    <dynamics damping="0.5" friction="0.1"/>
  </joint>
  <link name="fr_thigh_link">
    <inertial><mass value="1.5"/><origin xyz="0 0 -0.225" rpy="0 0 0"/>
      <inertia ixx="0.025" iyy="0.025" izz="0.002" ixy="0" ixz="0" iyz="0"/></inertial>
    <visual><origin xyz="0 0 -0.225" rpy="0 0 0"/>
      <geometry><box size="0.04 0.04 0.45"/></geometry><material name="orange"/></visual>
    <collision><origin xyz="0 0 -0.225" rpy="0 0 0"/>
      <geometry><box size="0.04 0.04 0.45"/></geometry></collision>
  </link>
  <joint name="fr_thigh_joint" type="revolute">
    <parent link="fr_hip_link"/><child link="fr_thigh_link"/>
    <origin xyz="0 0 -0.08" rpy="0 0 0"/><axis xyz="0 1 0"/>
    <limit lower="-0.1" upper="1.2" effort="500" velocity="3.0"/>
    <dynamics damping="0.5" friction="0.1"/>
  </joint>
  <link name="fr_shank_link">
    <inertial><mass value="1.0"/><origin xyz="0 0 -0.25" rpy="0 0 0"/>
      <inertia ixx="0.021" iyy="0.021" izz="0.001" ixy="0" ixz="0" iyz="0"/></inertial>
    <visual><origin xyz="0 0 -0.25" rpy="0 0 0"/>
      <geometry><box size="0.03 0.03 0.50"/></geometry><material name="dark_grey"/></visual>
    <collision><origin xyz="0 0 -0.25" rpy="0 0 0"/>
      <geometry><box size="0.03 0.03 0.50"/></geometry></collision>
  </link>
  <joint name="fr_knee_joint" type="revolute">
    <parent link="fr_thigh_link"/><child link="fr_shank_link"/>
    <origin xyz="0 0 -0.45" rpy="0 0 0"/><axis xyz="0 1 0"/>
    <limit lower="-2.0" upper="0.0" effort="800" velocity="5.0"/>
    <dynamics damping="0.8" friction="0.1"/>
  </joint>
  <link name="fr_foot_link">
    <inertial><mass value="0.2"/><origin xyz="0 0 0" rpy="0 0 0"/>
      <inertia ixx="0.0001" iyy="0.0001" izz="0.0001" ixy="0" ixz="0" iyz="0"/></inertial>
    <visual><origin xyz="0 0 0" rpy="0 0 0"/>
      <geometry><sphere radius="0.04"/></geometry><material name="light_grey"/></visual>
    <collision><origin xyz="0 0 0" rpy="0 0 0"/>
      <geometry><sphere radius="0.04"/></geometry></collision>
  </link>
  <joint name="fr_foot_joint" type="fixed">
    <parent link="fr_shank_link"/><child link="fr_foot_link"/>
    <origin xyz="0 0 -0.50" rpy="0 0 0"/>
  </joint>

  <!-- ── REAR-LEFT ── -->
  <link name="rl_hip_link">
    <inertial><mass value="0.5"/><origin xyz="0 0 0" rpy="0 0 0"/>
      <inertia ixx="0.001" iyy="0.001" izz="0.001" ixy="0" ixz="0" iyz="0"/></inertial>
    <visual><origin xyz="0 0 -0.04" rpy="0 0 0"/>
      <geometry><cylinder radius="0.03" length="0.08"/></geometry><material name="light_grey"/></visual>
    <collision><origin xyz="0 0 -0.04" rpy="0 0 0"/>
      <geometry><cylinder radius="0.03" length="0.08"/></geometry></collision>
  </link>
  <joint name="rl_hip_joint" type="revolute">
    <parent link="base_link"/><child link="rl_hip_link"/>
    <origin xyz="-0.35 0.18 -0.05" rpy="0 0 0"/><axis xyz="0 1 0"/>
    <limit lower="-0.6" upper="0.6" effort="300" velocity="3.0"/>
    <dynamics damping="0.5" friction="0.1"/>
  </joint>
  <link name="rl_thigh_link">
    <inertial><mass value="1.5"/><origin xyz="0 0 -0.225" rpy="0 0 0"/>
      <inertia ixx="0.025" iyy="0.025" izz="0.002" ixy="0" ixz="0" iyz="0"/></inertial>
    <visual><origin xyz="0 0 -0.225" rpy="0 0 0"/>
      <geometry><box size="0.04 0.04 0.45"/></geometry><material name="orange"/></visual>
    <collision><origin xyz="0 0 -0.225" rpy="0 0 0"/>
      <geometry><box size="0.04 0.04 0.45"/></geometry></collision>
  </link>
  <joint name="rl_thigh_joint" type="revolute">
    <parent link="rl_hip_link"/><child link="rl_thigh_link"/>
    <origin xyz="0 0 -0.08" rpy="0 0 0"/><axis xyz="0 1 0"/>
    <limit lower="-0.1" upper="1.2" effort="500" velocity="3.0"/>
    <dynamics damping="0.5" friction="0.1"/>
  </joint>
  <link name="rl_shank_link">
    <inertial><mass value="1.0"/><origin xyz="0 0 -0.25" rpy="0 0 0"/>
      <inertia ixx="0.021" iyy="0.021" izz="0.001" ixy="0" ixz="0" iyz="0"/></inertial>
    <visual><origin xyz="0 0 -0.25" rpy="0 0 0"/>
      <geometry><box size="0.03 0.03 0.50"/></geometry><material name="dark_grey"/></visual>
    <collision><origin xyz="0 0 -0.25" rpy="0 0 0"/>
      <geometry><box size="0.03 0.03 0.50"/></geometry></collision>
  </link>
  <joint name="rl_knee_joint" type="revolute">
    <parent link="rl_thigh_link"/><child link="rl_shank_link"/>
    <origin xyz="0 0 -0.45" rpy="0 0 0"/><axis xyz="0 1 0"/>
    <limit lower="-2.0" upper="0.0" effort="800" velocity="5.0"/>
    <dynamics damping="0.8" friction="0.1"/>
  </joint>
  <link name="rl_foot_link">
    <inertial><mass value="0.2"/><origin xyz="0 0 0" rpy="0 0 0"/>
      <inertia ixx="0.0001" iyy="0.0001" izz="0.0001" ixy="0" ixz="0" iyz="0"/></inertial>
    <visual><origin xyz="0 0 0" rpy="0 0 0"/>
      <geometry><sphere radius="0.04"/></geometry><material name="light_grey"/></visual>
    <collision><origin xyz="0 0 0" rpy="0 0 0"/>
      <geometry><sphere radius="0.04"/></geometry></collision>
  </link>
  <joint name="rl_foot_joint" type="fixed">
    <parent link="rl_shank_link"/><child link="rl_foot_link"/>
    <origin xyz="0 0 -0.50" rpy="0 0 0"/>
  </joint>

  <!-- ── REAR-RIGHT ── -->
  <link name="rr_hip_link">
    <inertial><mass value="0.5"/><origin xyz="0 0 0" rpy="0 0 0"/>
      <inertia ixx="0.001" iyy="0.001" izz="0.001" ixy="0" ixz="0" iyz="0"/></inertial>
    <visual><origin xyz="0 0 -0.04" rpy="0 0 0"/>
      <geometry><cylinder radius="0.03" length="0.08"/></geometry><material name="light_grey"/></visual>
    <collision><origin xyz="0 0 -0.04" rpy="0 0 0"/>
      <geometry><cylinder radius="0.03" length="0.08"/></geometry></collision>
  </link>
  <joint name="rr_hip_joint" type="revolute">
    <parent link="base_link"/><child link="rr_hip_link"/>
    <origin xyz="-0.35 -0.18 -0.05" rpy="0 0 0"/><axis xyz="0 1 0"/>
    <limit lower="-0.6" upper="0.6" effort="300" velocity="3.0"/>
    <dynamics damping="0.5" friction="0.1"/>
  </joint>
  <link name="rr_thigh_link">
    <inertial><mass value="1.5"/><origin xyz="0 0 -0.225" rpy="0 0 0"/>
      <inertia ixx="0.025" iyy="0.025" izz="0.002" ixy="0" ixz="0" iyz="0"/></inertial>
    <visual><origin xyz="0 0 -0.225" rpy="0 0 0"/>
      <geometry><box size="0.04 0.04 0.45"/></geometry><material name="orange"/></visual>
    <collision><origin xyz="0 0 -0.225" rpy="0 0 0"/>
      <geometry><box size="0.04 0.04 0.45"/></geometry></collision>
  </link>
  <joint name="rr_thigh_joint" type="revolute">
    <parent link="rr_hip_link"/><child link="rr_thigh_link"/>
    <origin xyz="0 0 -0.08" rpy="0 0 0"/><axis xyz="0 1 0"/>
    <limit lower="-0.1" upper="1.2" effort="500" velocity="3.0"/>
    <dynamics damping="0.5" friction="0.1"/>
  </joint>
  <link name="rr_shank_link">
    <inertial><mass value="1.0"/><origin xyz="0 0 -0.25" rpy="0 0 0"/>
      <inertia ixx="0.021" iyy="0.021" izz="0.001" ixy="0" ixz="0" iyz="0"/></inertial>
    <visual><origin xyz="0 0 -0.25" rpy="0 0 0"/>
      <geometry><box size="0.03 0.03 0.50"/></geometry><material name="dark_grey"/></visual>
    <collision><origin xyz="0 0 -0.25" rpy="0 0 0"/>
      <geometry><box size="0.03 0.03 0.50"/></geometry></collision>
  </link>
  <joint name="rr_knee_joint" type="revolute">
    <parent link="rr_thigh_link"/><child link="rr_shank_link"/>
    <origin xyz="0 0 -0.45" rpy="0 0 0"/><axis xyz="0 1 0"/>
    <limit lower="-2.0" upper="0.0" effort="800" velocity="5.0"/>
    <dynamics damping="0.8" friction="0.1"/>
  </joint>
  <link name="rr_foot_link">
    <inertial><mass value="0.2"/><origin xyz="0 0 0" rpy="0 0 0"/>
      <inertia ixx="0.0001" iyy="0.0001" izz="0.0001" ixy="0" ixz="0" iyz="0"/></inertial>
    <visual><origin xyz="0 0 0" rpy="0 0 0"/>
      <geometry><sphere radius="0.04"/></geometry><material name="light_grey"/></visual>
    <collision><origin xyz="0 0 0" rpy="0 0 0"/>
      <geometry><sphere radius="0.04"/></geometry></collision>
  </link>
  <joint name="rr_foot_joint" type="fixed">
    <parent link="rr_shank_link"/><child link="rr_foot_link"/>
    <origin xyz="0 0 -0.50" rpy="0 0 0"/>
  </joint>

</robot>
