<?xml version="1.0"?>
<!--
  Highland Cow — PyBullet-compatible URDF
  ========================================
  Stocky, low-CoM quadruped robot.  86 kg total body mass.

  Leg layout (top view):
      FL ———— FR        +X = forward
      |  body  |        +Y = left
      RL ———— RR        +Z = up

  3-segment legs: thigh (0.20 m) + shank (0.18 m) + cannon (0.10 m) + hoof (r 0.04 m)
  16 controlled joints: 4 legs × (hip Z-yaw + thigh Y-pitch + knee Y-pitch + cannon Y-pitch)
  Cannon bone is driven passively by pantograph:
      cannon_angle = 0.08 − (thigh + knee)

  Compatible with PyBullet — NO Gazebo plugins or ros2_control tags.
-->
<robot name="robotic_horse">

  <!-- ════════════════════════════════════════════════════════════
       MATERIALS
  ════════════════════════════════════════════════════════════ -->
  <material name="dark_grey">
    <color rgba="0.2 0.2 0.2 1"/>
  </material>
  <material name="orange">
    <color rgba="0.9 0.4 0.0 1"/>
  </material>
  <material name="light_grey">
    <color rgba="0.7 0.7 0.7 1"/>
  </material>
  <material name="black">
    <color rgba="0.05 0.05 0.05 1"/>
  </material>
  <material name="silver">
    <color rgba="0.75 0.75 0.80 1"/>
  </material>
  <material name="body_panel">
    <color rgba="0.25 0.25 0.30 1"/>
  </material>
  <material name="wood">
    <color rgba="0.55 0.35 0.15 1"/>
  </material>
  <material name="iron">
    <color rgba="0.28 0.28 0.28 1"/>
  </material>

  <!-- ════════════════════════════════════════════════════════════
       BASE / BODY   (1.40 × 0.60 × 0.40 m, 86 kg)
  ════════════════════════════════════════════════════════════ -->
  <link name="base_link">
    <inertial>
      <mass value="86.0"/>
      <origin xyz="0 0 0" rpy="0 0 0"/>
      <inertia ixx="3.73" iyy="15.19" izz="16.63" ixy="0" ixz="0" iyz="0"/>
    </inertial>
    <visual>
      <origin xyz="0 0 0" rpy="0 0 0"/>
      <geometry><box size="1.40 0.60 0.40"/></geometry>
      <material name="dark_grey"/>
    </visual>
    <collision>
      <origin xyz="0 0 0" rpy="0 0 0"/>
      <geometry><box size="1.40 0.60 0.40"/></geometry>
    </collision>
  </link>

  <!-- ════════════════════════════════════════════════════════════
       HEAD (decorative, fixed to body)
  ════════════════════════════════════════════════════════════ -->

  <!-- Neck -->
  <link name="neck_link">
    <inertial>
      <mass value="3.0"/>
      <origin xyz="0 0 0" rpy="0 0 0"/>
      <inertia ixx="0.020" iyy="0.018" izz="0.015" ixy="0" ixz="0" iyz="0"/>
    </inertial>
    <visual>
      <origin xyz="0 0 0" rpy="0 0 0"/>
      <geometry><box size="0.22 0.24 0.26"/></geometry>
      <material name="body_panel"/>
    </visual>
    <collision>
      <origin xyz="0 0 0" rpy="0 0 0"/>
      <geometry><box size="0.22 0.24 0.26"/></geometry>
    </collision>
  </link>

  <joint name="neck_joint" type="fixed">
    <parent link="base_link"/>
    <child link="neck_link"/>
    <origin xyz="0.68 0 0.12" rpy="0 -0.10 0"/>
  </joint>

  <!-- Head -->
  <link name="head_link">
    <inertial>
      <mass value="2.5"/>
      <origin xyz="0 0 0" rpy="0 0 0"/>
      <inertia ixx="0.022" iyy="0.015" izz="0.020" ixy="0" ixz="0" iyz="0"/>
    </inertial>
    <!-- Skull -->
    <visual>
      <origin xyz="0 0 0" rpy="0 0 0"/>
      <geometry><box size="0.38 0.34 0.28"/></geometry>
      <material name="dark_grey"/>
    </visual>
    <!-- Muzzle -->
    <visual>
      <origin xyz="0.18 0 -0.06" rpy="0 0 0"/>
      <geometry><box size="0.14 0.18 0.14"/></geometry>
      <material name="body_panel"/>
    </visual>
    <!-- Left horn -->
    <visual>
      <origin xyz="-0.04 0.18 0.10" rpy="0 0.45 0.30"/>
      <geometry><cylinder radius="0.025" length="0.50"/></geometry>
      <material name="silver"/>
    </visual>
    <!-- Right horn -->
    <visual>
      <origin xyz="-0.04 -0.18 0.10" rpy="0 0.45 -0.30"/>
      <geometry><cylinder radius="0.025" length="0.50"/></geometry>
      <material name="silver"/>
    </visual>
    <collision>
      <origin xyz="0 0 0" rpy="0 0 0"/>
      <geometry><box size="0.38 0.34 0.28"/></geometry>
    </collision>
  </link>

  <joint name="head_joint" type="fixed">
    <parent link="neck_link"/>
    <child link="head_link"/>
    <origin xyz="0.20 0 0.12" rpy="0 0.10 0"/>
  </joint>

  <!-- ════════════════════════════════════════════════════════════
       FRONT-LEFT LEG  (FL)
       Hip at xyz="0.48  0.24  -0.16" from base_link
  ════════════════════════════════════════════════════════════ -->

  <link name="fl_hip_link">
    <inertial>
      <mass value="4.0"/>
      <origin xyz="0 0 -0.06" rpy="0 0 0"/>
      <inertia ixx="0.012" iyy="0.012" izz="0.007" ixy="0" ixz="0" iyz="0"/>
    </inertial>
    <visual>
      <origin xyz="0 0 -0.06" rpy="0 0 0"/>
      <geometry><cylinder radius="0.05" length="0.12"/></geometry>
      <material name="light_grey"/>
    </visual>
    <collision>
      <origin xyz="0 0 -0.06" rpy="0 0 0"/>
      <geometry><cylinder radius="0.05" length="0.12"/></geometry>
    </collision>
  </link>

  <joint name="fl_hip_joint" type="revolute">
    <parent link="base_link"/>
    <child link="fl_hip_link"/>
    <origin xyz="0.48 0.24 -0.16" rpy="0 0 0"/>
    <axis xyz="0 0 1"/>
    <limit lower="-0.35" upper="0.35" effort="200" velocity="2.0"/>
    <dynamics damping="2.5" friction="0.3"/>
  </joint>

  <link name="fl_thigh_link">
    <inertial>
      <mass value="6.0"/>
      <origin xyz="0 0 -0.10" rpy="0 0 0"/>
      <inertia ixx="0.022" iyy="0.022" izz="0.005" ixy="0" ixz="0" iyz="0"/>
    </inertial>
    <!-- Main thigh tube -->
    <visual>
      <origin xyz="0 0 -0.10" rpy="0 0 0"/>
      <geometry><box size="0.070 0.070 0.20"/></geometry>
      <material name="orange"/>
    </visual>
    <!-- Ballscrew tube -->
    <visual>
      <origin xyz="0.040 0 -0.10" rpy="0 0 0"/>
      <geometry><cylinder radius="0.018" length="0.13"/></geometry>
      <material name="silver"/>
    </visual>
    <collision>
      <origin xyz="0 0 -0.10" rpy="0 0 0"/>
      <geometry><box size="0.070 0.070 0.20"/></geometry>
    </collision>
  </link>

  <joint name="fl_thigh_joint" type="revolute">
    <parent link="fl_hip_link"/>
    <child link="fl_thigh_link"/>
    <origin xyz="0 0 -0.10" rpy="0 0 0"/>
    <axis xyz="0 1 0"/>
    <limit lower="-1.8" upper="1.8" effort="500" velocity="3.0"/>
    <dynamics damping="2.5" friction="0.3"/>
  </joint>

  <link name="fl_shank_link">
    <inertial>
      <mass value="5.0"/>
      <origin xyz="0 0 -0.09" rpy="0 0 0"/>
      <inertia ixx="0.015" iyy="0.015" izz="0.003" ixy="0" ixz="0" iyz="0"/>
    </inertial>
    <visual>
      <origin xyz="0 0 -0.09" rpy="0 0 0"/>
      <geometry><box size="0.050 0.050 0.18"/></geometry>
      <material name="dark_grey"/>
    </visual>
    <collision>
      <origin xyz="0 0 -0.09" rpy="0 0 0"/>
      <geometry><box size="0.050 0.050 0.18"/></geometry>
    </collision>
  </link>

  <joint name="fl_knee_joint" type="revolute">
    <parent link="fl_thigh_link"/>
    <child link="fl_shank_link"/>
    <origin xyz="0 0 -0.20" rpy="0 0 0"/>
    <axis xyz="0 1 0"/>
    <limit lower="-1.8" upper="2.0" effort="800" velocity="5.0"/>
    <dynamics damping="3.5" friction="0.3"/>
  </joint>

  <link name="fl_cannon_link">
    <inertial>
      <mass value="1.2"/>
      <origin xyz="0 0 -0.05" rpy="0 0 0"/>
      <inertia ixx="0.0011" iyy="0.0011" izz="0.0002" ixy="0" ixz="0" iyz="0"/>
    </inertial>
    <visual>
      <origin xyz="0 0 -0.05" rpy="0 0 0"/>
      <geometry><cylinder radius="0.018" length="0.10"/></geometry>
      <material name="light_grey"/>
    </visual>
    <collision>
      <origin xyz="0 0 -0.05" rpy="0 0 0"/>
      <geometry><cylinder radius="0.018" length="0.10"/></geometry>
    </collision>
  </link>

  <joint name="fl_cannon_joint" type="revolute">
    <parent link="fl_shank_link"/>
    <child link="fl_cannon_link"/>
    <origin xyz="0 0 -0.18" rpy="0 0 0"/>
    <axis xyz="0 1 0"/>
    <limit lower="-2.0" upper="2.0" effort="100" velocity="6.0"/>
    <dynamics damping="1.0" friction="0.1"/>
  </joint>

  <link name="fl_foot_link">
    <inertial>
      <mass value="0.4"/>
      <origin xyz="0 0 0" rpy="0 0 0"/>
      <inertia ixx="0.00026" iyy="0.00026" izz="0.00026" ixy="0" ixz="0" iyz="0"/>
    </inertial>
    <visual>
      <origin xyz="0 0 0" rpy="0 0 0"/>
      <geometry><sphere radius="0.04"/></geometry>
      <material name="black"/>
    </visual>
    <collision>
      <origin xyz="0 0 0" rpy="0 0 0"/>
      <geometry><sphere radius="0.04"/></geometry>
    </collision>
  </link>

  <joint name="fl_foot_joint" type="fixed">
    <parent link="fl_cannon_link"/>
    <child link="fl_foot_link"/>
    <origin xyz="0 0 -0.10" rpy="0 0 0"/>
  </joint>

  <!-- ════════════════════════════════════════════════════════════
       FRONT-RIGHT LEG  (FR)
       Hip at xyz="0.48  -0.24  -0.16" from base_link
  ════════════════════════════════════════════════════════════ -->

  <link name="fr_hip_link">
    <inertial>
      <mass value="4.0"/>
      <origin xyz="0 0 -0.06" rpy="0 0 0"/>
      <inertia ixx="0.012" iyy="0.012" izz="0.007" ixy="0" ixz="0" iyz="0"/>
    </inertial>
    <visual>
      <origin xyz="0 0 -0.06" rpy="0 0 0"/>
      <geometry><cylinder radius="0.05" length="0.12"/></geometry>
      <material name="light_grey"/>
    </visual>
    <collision>
      <origin xyz="0 0 -0.06" rpy="0 0 0"/>
      <geometry><cylinder radius="0.05" length="0.12"/></geometry>
    </collision>
  </link>

  <joint name="fr_hip_joint" type="revolute">
    <parent link="base_link"/>
    <child link="fr_hip_link"/>
    <origin xyz="0.48 -0.24 -0.16" rpy="0 0 0"/>
    <axis xyz="0 0 1"/>
    <limit lower="-0.35" upper="0.35" effort="200" velocity="2.0"/>
    <dynamics damping="2.5" friction="0.3"/>
  </joint>

  <link name="fr_thigh_link">
    <inertial>
      <mass value="6.0"/>
      <origin xyz="0 0 -0.10" rpy="0 0 0"/>
      <inertia ixx="0.022" iyy="0.022" izz="0.005" ixy="0" ixz="0" iyz="0"/>
    </inertial>
    <visual>
      <origin xyz="0 0 -0.10" rpy="0 0 0"/>
      <geometry><box size="0.070 0.070 0.20"/></geometry>
      <material name="orange"/>
    </visual>
    <visual>
      <origin xyz="0.040 0 -0.10" rpy="0 0 0"/>
      <geometry><cylinder radius="0.018" length="0.13"/></geometry>
      <material name="silver"/>
    </visual>
    <collision>
      <origin xyz="0 0 -0.10" rpy="0 0 0"/>
      <geometry><box size="0.070 0.070 0.20"/></geometry>
    </collision>
  </link>

  <joint name="fr_thigh_joint" type="revolute">
    <parent link="fr_hip_link"/>
    <child link="fr_thigh_link"/>
    <origin xyz="0 0 -0.10" rpy="0 0 0"/>
    <axis xyz="0 1 0"/>
    <limit lower="-1.8" upper="1.8" effort="500" velocity="3.0"/>
    <dynamics damping="2.5" friction="0.3"/>
  </joint>

  <link name="fr_shank_link">
    <inertial>
      <mass value="5.0"/>
      <origin xyz="0 0 -0.09" rpy="0 0 0"/>
      <inertia ixx="0.015" iyy="0.015" izz="0.003" ixy="0" ixz="0" iyz="0"/>
    </inertial>
    <visual>
      <origin xyz="0 0 -0.09" rpy="0 0 0"/>
      <geometry><box size="0.050 0.050 0.18"/></geometry>
      <material name="dark_grey"/>
    </visual>
    <collision>
      <origin xyz="0 0 -0.09" rpy="0 0 0"/>
      <geometry><box size="0.050 0.050 0.18"/></geometry>
    </collision>
  </link>

  <joint name="fr_knee_joint" type="revolute">
    <parent link="fr_thigh_link"/>
    <child link="fr_shank_link"/>
    <origin xyz="0 0 -0.20" rpy="0 0 0"/>
    <axis xyz="0 1 0"/>
    <limit lower="-1.8" upper="2.0" effort="800" velocity="5.0"/>
    <dynamics damping="3.5" friction="0.3"/>
  </joint>

  <link name="fr_cannon_link">
    <inertial>
      <mass value="1.2"/>
      <origin xyz="0 0 -0.05" rpy="0 0 0"/>
      <inertia ixx="0.0011" iyy="0.0011" izz="0.0002" ixy="0" ixz="0" iyz="0"/>
    </inertial>
    <visual>
      <origin xyz="0 0 -0.05" rpy="0 0 0"/>
      <geometry><cylinder radius="0.018" length="0.10"/></geometry>
      <material name="light_grey"/>
    </visual>
    <collision>
      <origin xyz="0 0 -0.05" rpy="0 0 0"/>
      <geometry><cylinder radius="0.018" length="0.10"/></geometry>
    </collision>
  </link>

  <joint name="fr_cannon_joint" type="revolute">
    <parent link="fr_shank_link"/>
    <child link="fr_cannon_link"/>
    <origin xyz="0 0 -0.18" rpy="0 0 0"/>
    <axis xyz="0 1 0"/>
    <limit lower="-2.0" upper="2.0" effort="100" velocity="6.0"/>
    <dynamics damping="1.0" friction="0.1"/>
  </joint>

  <link name="fr_foot_link">
    <inertial>
      <mass value="0.4"/>
      <origin xyz="0 0 0" rpy="0 0 0"/>
      <inertia ixx="0.00026" iyy="0.00026" izz="0.00026" ixy="0" ixz="0" iyz="0"/>
    </inertial>
    <visual>
      <origin xyz="0 0 0" rpy="0 0 0"/>
      <geometry><sphere radius="0.04"/></geometry>
      <material name="black"/>
    </visual>
    <collision>
      <origin xyz="0 0 0" rpy="0 0 0"/>
      <geometry><sphere radius="0.04"/></geometry>
    </collision>
  </link>

  <joint name="fr_foot_joint" type="fixed">
    <parent link="fr_cannon_link"/>
    <child link="fr_foot_link"/>
    <origin xyz="0 0 -0.10" rpy="0 0 0"/>
  </joint>

  <!-- ════════════════════════════════════════════════════════════
       REAR-LEFT LEG  (RL)
       Hip at xyz="-0.48  0.24  -0.16" from base_link
  ════════════════════════════════════════════════════════════ -->

  <link name="rl_hip_link">
    <inertial>
      <mass value="4.0"/>
      <origin xyz="0 0 -0.06" rpy="0 0 0"/>
      <inertia ixx="0.012" iyy="0.012" izz="0.007" ixy="0" ixz="0" iyz="0"/>
    </inertial>
    <visual>
      <origin xyz="0 0 -0.06" rpy="0 0 0"/>
      <geometry><cylinder radius="0.05" length="0.12"/></geometry>
      <material name="light_grey"/>
    </visual>
    <collision>
      <origin xyz="0 0 -0.06" rpy="0 0 0"/>
      <geometry><cylinder radius="0.05" length="0.12"/></geometry>
    </collision>
  </link>

  <joint name="rl_hip_joint" type="revolute">
    <parent link="base_link"/>
    <child link="rl_hip_link"/>
    <origin xyz="-0.48 0.24 -0.16" rpy="0 0 0"/>
    <axis xyz="0 0 1"/>
    <limit lower="-0.35" upper="0.35" effort="200" velocity="2.0"/>
    <dynamics damping="2.5" friction="0.3"/>
  </joint>

  <link name="rl_thigh_link">
    <inertial>
      <mass value="6.0"/>
      <origin xyz="0 0 -0.10" rpy="0 0 0"/>
      <inertia ixx="0.022" iyy="0.022" izz="0.005" ixy="0" ixz="0" iyz="0"/>
    </inertial>
    <visual>
      <origin xyz="0 0 -0.10" rpy="0 0 0"/>
      <geometry><box size="0.070 0.070 0.20"/></geometry>
      <material name="orange"/>
    </visual>
    <visual>
      <origin xyz="0.040 0 -0.10" rpy="0 0 0"/>
      <geometry><cylinder radius="0.018" length="0.13"/></geometry>
      <material name="silver"/>
    </visual>
    <collision>
      <origin xyz="0 0 -0.10" rpy="0 0 0"/>
      <geometry><box size="0.070 0.070 0.20"/></geometry>
    </collision>
  </link>

  <joint name="rl_thigh_joint" type="revolute">
    <parent link="rl_hip_link"/>
    <child link="rl_thigh_link"/>
    <origin xyz="0 0 -0.10" rpy="0 0 0"/>
    <axis xyz="0 1 0"/>
    <limit lower="-1.8" upper="1.8" effort="500" velocity="3.0"/>
    <dynamics damping="2.5" friction="0.3"/>
  </joint>

  <link name="rl_shank_link">
    <inertial>
      <mass value="5.0"/>
      <origin xyz="0 0 -0.09" rpy="0 0 0"/>
      <inertia ixx="0.015" iyy="0.015" izz="0.003" ixy="0" ixz="0" iyz="0"/>
    </inertial>
    <visual>
      <origin xyz="0 0 -0.09" rpy="0 0 0"/>
      <geometry><box size="0.050 0.050 0.18"/></geometry>
      <material name="dark_grey"/>
    </visual>
    <collision>
      <origin xyz="0 0 -0.09" rpy="0 0 0"/>
      <geometry><box size="0.050 0.050 0.18"/></geometry>
    </collision>
  </link>

  <joint name="rl_knee_joint" type="revolute">
    <parent link="rl_thigh_link"/>
    <child link="rl_shank_link"/>
    <origin xyz="0 0 -0.20" rpy="0 0 0"/>
    <axis xyz="0 1 0"/>
    <limit lower="-1.8" upper="2.0" effort="800" velocity="5.0"/>
    <dynamics damping="3.5" friction="0.3"/>
  </joint>

  <link name="rl_cannon_link">
    <inertial>
      <mass value="1.2"/>
      <origin xyz="0 0 -0.05" rpy="0 0 0"/>
      <inertia ixx="0.0011" iyy="0.0011" izz="0.0002" ixy="0" ixz="0" iyz="0"/>
    </inertial>
    <visual>
      <origin xyz="0 0 -0.05" rpy="0 0 0"/>
      <geometry><cylinder radius="0.018" length="0.10"/></geometry>
      <material name="light_grey"/>
    </visual>
    <collision>
      <origin xyz="0 0 -0.05" rpy="0 0 0"/>
      <geometry><cylinder radius="0.018" length="0.10"/></geometry>
    </collision>
  </link>

  <joint name="rl_cannon_joint" type="revolute">
    <parent link="rl_shank_link"/>
    <child link="rl_cannon_link"/>
    <origin xyz="0 0 -0.18" rpy="0 0 0"/>
    <axis xyz="0 1 0"/>
    <limit lower="-2.0" upper="2.0" effort="100" velocity="6.0"/>
    <dynamics damping="1.0" friction="0.1"/>
  </joint>

  <link name="rl_foot_link">
    <inertial>
      <mass value="0.4"/>
      <origin xyz="0 0 0" rpy="0 0 0"/>
      <inertia ixx="0.00026" iyy="0.00026" izz="0.00026" ixy="0" ixz="0" iyz="0"/>
    </inertial>
    <visual>
      <origin xyz="0 0 0" rpy="0 0 0"/>
      <geometry><sphere radius="0.04"/></geometry>
      <material name="black"/>
    </visual>
    <collision>
      <origin xyz="0 0 0" rpy="0 0 0"/>
      <geometry><sphere radius="0.04"/></geometry>
    </collision>
  </link>

  <joint name="rl_foot_joint" type="fixed">
    <parent link="rl_cannon_link"/>
    <child link="rl_foot_link"/>
    <origin xyz="0 0 -0.10" rpy="0 0 0"/>
  </joint>

  <!-- ════════════════════════════════════════════════════════════
       REAR-RIGHT LEG  (RR)
       Hip at xyz="-0.48  -0.24  -0.16" from base_link
  ════════════════════════════════════════════════════════════ -->

  <link name="rr_hip_link">
    <inertial>
      <mass value="4.0"/>
      <origin xyz="0 0 -0.06" rpy="0 0 0"/>
      <inertia ixx="0.012" iyy="0.012" izz="0.007" ixy="0" ixz="0" iyz="0"/>
    </inertial>
    <visual>
      <origin xyz="0 0 -0.06" rpy="0 0 0"/>
      <geometry><cylinder radius="0.05" length="0.12"/></geometry>
      <material name="light_grey"/>
    </visual>
    <collision>
      <origin xyz="0 0 -0.06" rpy="0 0 0"/>
      <geometry><cylinder radius="0.05" length="0.12"/></geometry>
    </collision>
  </link>

  <joint name="rr_hip_joint" type="revolute">
    <parent link="base_link"/>
    <child link="rr_hip_link"/>
    <origin xyz="-0.48 -0.24 -0.16" rpy="0 0 0"/>
    <axis xyz="0 0 1"/>
    <limit lower="-0.35" upper="0.35" effort="200" velocity="2.0"/>
    <dynamics damping="2.5" friction="0.3"/>
  </joint>

  <link name="rr_thigh_link">
    <inertial>
      <mass value="6.0"/>
      <origin xyz="0 0 -0.10" rpy="0 0 0"/>
      <inertia ixx="0.022" iyy="0.022" izz="0.005" ixy="0" ixz="0" iyz="0"/>
    </inertial>
    <visual>
      <origin xyz="0 0 -0.10" rpy="0 0 0"/>
      <geometry><box size="0.070 0.070 0.20"/></geometry>
      <material name="orange"/>
    </visual>
    <visual>
      <origin xyz="0.040 0 -0.10" rpy="0 0 0"/>
      <geometry><cylinder radius="0.018" length="0.13"/></geometry>
      <material name="silver"/>
    </visual>
    <collision>
      <origin xyz="0 0 -0.10" rpy="0 0 0"/>
      <geometry><box size="0.070 0.070 0.20"/></geometry>
    </collision>
  </link>

  <joint name="rr_thigh_joint" type="revolute">
    <parent link="rr_hip_link"/>
    <child link="rr_thigh_link"/>
    <origin xyz="0 0 -0.10" rpy="0 0 0"/>
    <axis xyz="0 1 0"/>
    <limit lower="-1.8" upper="1.8" effort="500" velocity="3.0"/>
    <dynamics damping="2.5" friction="0.3"/>
  </joint>

  <link name="rr_shank_link">
    <inertial>
      <mass value="5.0"/>
      <origin xyz="0 0 -0.09" rpy="0 0 0"/>
      <inertia ixx="0.015" iyy="0.015" izz="0.003" ixy="0" ixz="0" iyz="0"/>
    </inertial>
    <visual>
      <origin xyz="0 0 -0.09" rpy="0 0 0"/>
      <geometry><box size="0.050 0.050 0.18"/></geometry>
      <material name="dark_grey"/>
    </visual>
    <collision>
      <origin xyz="0 0 -0.09" rpy="0 0 0"/>
      <geometry><box size="0.050 0.050 0.18"/></geometry>
    </collision>
  </link>

  <joint name="rr_knee_joint" type="revolute">
    <parent link="rr_thigh_link"/>
    <child link="rr_shank_link"/>
    <origin xyz="0 0 -0.20" rpy="0 0 0"/>
    <axis xyz="0 1 0"/>
    <limit lower="-1.8" upper="2.0" effort="800" velocity="5.0"/>
    <dynamics damping="3.5" friction="0.3"/>
  </joint>

  <link name="rr_cannon_link">
    <inertial>
      <mass value="1.2"/>
      <origin xyz="0 0 -0.05" rpy="0 0 0"/>
      <inertia ixx="0.0011" iyy="0.0011" izz="0.0002" ixy="0" ixz="0" iyz="0"/>
    </inertial>
    <visual>
      <origin xyz="0 0 -0.05" rpy="0 0 0"/>
      <geometry><cylinder radius="0.018" length="0.10"/></geometry>
      <material name="light_grey"/>
    </visual>
    <collision>
      <origin xyz="0 0 -0.05" rpy="0 0 0"/>
      <geometry><cylinder radius="0.018" length="0.10"/></geometry>
    </collision>
  </link>

  <joint name="rr_cannon_joint" type="revolute">
    <parent link="rr_shank_link"/>
    <child link="rr_cannon_link"/>
    <origin xyz="0 0 -0.18" rpy="0 0 0"/>
    <axis xyz="0 1 0"/>
    <limit lower="-2.0" upper="2.0" effort="100" velocity="6.0"/>
    <dynamics damping="1.0" friction="0.1"/>
  </joint>

  <link name="rr_foot_link">
    <inertial>
      <mass value="0.4"/>
      <origin xyz="0 0 0" rpy="0 0 0"/>
      <inertia ixx="0.00026" iyy="0.00026" izz="0.00026" ixy="0" ixz="0" iyz="0"/>
    </inertial>
    <visual>
      <origin xyz="0 0 0" rpy="0 0 0"/>
      <geometry><sphere radius="0.04"/></geometry>
      <material name="black"/>
    </visual>
    <collision>
      <origin xyz="0 0 0" rpy="0 0 0"/>
      <geometry><sphere radius="0.04"/></geometry>
    </collision>
  </link>

  <joint name="rr_foot_joint" type="fixed">
    <parent link="rr_cannon_link"/>
    <child link="rr_foot_link"/>
    <origin xyz="0 0 -0.10" rpy="0 0 0"/>
  </joint>
  <!-- ════════════════════════════════════════════════════════════
       CARRIAGE — hitched behind the horse
       Total carriage mass ≈ 64 kg (+ 30 kg payload)
       Front wheels ⌀ 85 cm, Rear wheels ⌀ 105 cm
       Track 140 cm, Wheelbase 205 cm
  ════════════════════════════════════════════════════════════ -->

  <!-- Hitch yaw (base_link → hitch_link) -->
  <joint name="horse_hitch_joint" type="revolute">
    <parent link="base_link"/>
    <child link="hitch_link"/>
    <origin xyz="-0.70 0 -0.10" rpy="0 0 0"/>
    <axis xyz="0 0 1"/>
    <limit lower="-0.5" upper="0.5" effort="0" velocity="2.0"/>
    <dynamics damping="5.0" friction="0.1"/>
  </joint>
  <link name="hitch_link">
    <inertial>
      <mass value="1.0"/>
      <origin xyz="0 0 0" rpy="0 0 0"/>
      <inertia ixx="0.001" iyy="0.001" izz="0.0005" ixy="0" ixz="0" iyz="0"/>
    </inertial>
    <visual>
      <origin xyz="0 0 0" rpy="0 0 0"/>
      <geometry><cylinder radius="0.03" length="0.10"/></geometry>
      <material name="iron"/>
    </visual>
    <collision>
      <origin xyz="0 0 0" rpy="0 0 0"/>
      <geometry><cylinder radius="0.03" length="0.10"/></geometry>
    </collision>
  </link>

  <!-- Hitch pitch (hitch_link → tongue_link) -->
  <joint name="hitch_pitch_joint" type="revolute">
    <parent link="hitch_link"/>
    <child link="tongue_link"/>
    <origin xyz="0 0 0" rpy="0 0 0"/>
    <axis xyz="0 1 0"/>
    <limit lower="-0.3" upper="0.3" effort="0" velocity="2.0"/>
    <dynamics damping="10.0" friction="0.1"/>
  </joint>
  <link name="tongue_link">
    <inertial>
      <mass value="5.0"/>
      <origin xyz="-0.40 0 0" rpy="0 0 0"/>
      <inertia ixx="0.001" iyy="0.027" izz="0.027" ixy="0" ixz="0" iyz="0"/>
    </inertial>
    <visual>
      <origin xyz="-0.40 0 0" rpy="0 0 0"/>
      <geometry><box size="0.80 0.06 0.04"/></geometry>
      <material name="wood"/>
    </visual>
    <collision>
      <origin xyz="-0.40 0 0" rpy="0 0 0"/>
      <geometry><box size="0.80 0.06 0.04"/></geometry>
    </collision>
  </link>

  <!-- Cart base (tongue_link → cart_base_link) -->
  <joint name="cart_base_joint" type="fixed">
    <parent link="tongue_link"/>
    <child link="cart_base_link"/>
    <origin xyz="-0.80 0 0.10" rpy="0 0 0"/>
  </joint>
  <link name="cart_base_link">
    <inertial>
      <mass value="34.0"/>
      <origin xyz="-0.60 0 0" rpy="0 0 0"/>
      <inertia ixx="1.82" iyy="4.08" izz="5.90" ixy="0" ixz="0" iyz="0"/>
    </inertial>
    <visual>
      <origin xyz="-0.60 0 0" rpy="0 0 0"/>
      <geometry><box size="1.20 0.80 0.05"/></geometry>
      <material name="wood"/>
    </visual>
    <collision>
      <origin xyz="-0.60 0 0" rpy="0 0 0"/>
      <geometry><box size="1.20 0.80 0.05"/></geometry>
    </collision>
    <visual>
      <origin xyz="-0.80 0 0.175" rpy="0 0 0"/>
      <geometry><box size="0.40 0.70 0.30"/></geometry>
      <material name="wood"/>
    </visual>
    <collision>
      <origin xyz="-0.80 0 0.175" rpy="0 0 0"/>
      <geometry><box size="0.40 0.70 0.30"/></geometry>
    </collision>
  </link>

  <!-- Front axle (steering) -->
  <joint name="front_axle_joint" type="revolute">
    <parent link="cart_base_link"/>
    <child link="front_axle_link"/>
    <origin xyz="-0.10 0 -0.05" rpy="0 0 0"/>
    <axis xyz="0 0 1"/>
    <limit lower="-0.4" upper="0.4" effort="0" velocity="2.0"/>
    <dynamics damping="20.0" friction="0.1"/>
  </joint>
  <link name="front_axle_link">
    <inertial>
      <mass value="3.0"/>
      <origin xyz="0 0 0" rpy="0 0 0"/>
      <inertia ixx="0.423" iyy="0.001" izz="0.423" ixy="0" ixz="0" iyz="0"/>
    </inertial>
    <visual>
      <origin xyz="0 0 0" rpy="0 0 0"/>
      <geometry><box size="0.06 1.30 0.06"/></geometry>
      <material name="iron"/>
    </visual>
    <collision>
      <origin xyz="0 0 0" rpy="0 0 0"/>
      <geometry><box size="0.06 1.30 0.06"/></geometry>
    </collision>
  </link>

  <!-- Rear axle (fixed) -->
  <joint name="rear_axle_joint" type="fixed">
    <parent link="cart_base_link"/>
    <child link="rear_axle_link"/>
    <origin xyz="-1.15 0 -0.05" rpy="0 0 0"/>
  </joint>
  <link name="rear_axle_link">
    <inertial>
      <mass value="3.0"/>
      <origin xyz="0 0 0" rpy="0 0 0"/>
      <inertia ixx="0.423" iyy="0.001" izz="0.423" ixy="0" ixz="0" iyz="0"/>
    </inertial>
    <visual>
      <origin xyz="0 0 0" rpy="0 0 0"/>
      <geometry><box size="0.06 1.30 0.06"/></geometry>
      <material name="iron"/>
    </visual>
    <collision>
      <origin xyz="0 0 0" rpy="0 0 0"/>
      <geometry><box size="0.06 1.30 0.06"/></geometry>
    </collision>
  </link>

  <!-- Front-Left Wheel -->
  <joint name="cart_fl_wheel_joint" type="continuous">
    <parent link="front_axle_link"/>
    <child link="cart_fl_wheel_link"/>
    <origin xyz="0 0.70 0" rpy="0 0 0"/>
    <axis xyz="0 1 0"/>
    <dynamics damping="0.5" friction="0.1"/>
  </joint>
  <link name="cart_fl_wheel_link">
    <inertial>
      <mass value="4.0"/>
      <origin xyz="0 0 0" rpy="0 0 0"/>
      <inertia ixx="0.182" iyy="0.361" izz="0.182" ixy="0" ixz="0" iyz="0"/>
    </inertial>
    <visual>
      <origin xyz="0 0 0" rpy="1.5708 0 0"/>
      <geometry><cylinder radius="0.425" length="0.06"/></geometry>
      <material name="dark_grey"/>
    </visual>
    <collision>
      <origin xyz="0 0 0" rpy="1.5708 0 0"/>
      <geometry><cylinder radius="0.425" length="0.06"/></geometry>
    </collision>
  </link>

  <!-- Front-Right Wheel -->
  <joint name="cart_fr_wheel_joint" type="continuous">
    <parent link="front_axle_link"/>
    <child link="cart_fr_wheel_link"/>
    <origin xyz="0 -0.70 0" rpy="0 0 0"/>
    <axis xyz="0 1 0"/>
    <dynamics damping="0.5" friction="0.1"/>
  </joint>
  <link name="cart_fr_wheel_link">
    <inertial>
      <mass value="4.0"/>
      <origin xyz="0 0 0" rpy="0 0 0"/>
      <inertia ixx="0.182" iyy="0.361" izz="0.182" ixy="0" ixz="0" iyz="0"/>
    </inertial>
    <visual>
      <origin xyz="0 0 0" rpy="1.5708 0 0"/>
      <geometry><cylinder radius="0.425" length="0.06"/></geometry>
      <material name="dark_grey"/>
    </visual>
    <collision>
      <origin xyz="0 0 0" rpy="1.5708 0 0"/>
      <geometry><cylinder radius="0.425" length="0.06"/></geometry>
    </collision>
  </link>

  <!-- Rear-Left Wheel -->
  <joint name="cart_rl_wheel_joint" type="continuous">
    <parent link="rear_axle_link"/>
    <child link="cart_rl_wheel_link"/>
    <origin xyz="0 0.70 0" rpy="0 0 0"/>
    <axis xyz="0 1 0"/>
    <dynamics damping="0.5" friction="0.1"/>
  </joint>
  <link name="cart_rl_wheel_link">
    <inertial>
      <mass value="5.0"/>
      <origin xyz="0 0 0" rpy="0 0 0"/>
      <inertia ixx="0.347" iyy="0.689" izz="0.347" ixy="0" ixz="0" iyz="0"/>
    </inertial>
    <visual>
      <origin xyz="0 0 0" rpy="1.5708 0 0"/>
      <geometry><cylinder radius="0.525" length="0.08"/></geometry>
      <material name="dark_grey"/>
    </visual>
    <collision>
      <origin xyz="0 0 0" rpy="1.5708 0 0"/>
      <geometry><cylinder radius="0.525" length="0.08"/></geometry>
    </collision>
  </link>

  <!-- Rear-Right Wheel -->
  <joint name="cart_rr_wheel_joint" type="continuous">
    <parent link="rear_axle_link"/>
    <child link="cart_rr_wheel_link"/>
    <origin xyz="0 -0.70 0" rpy="0 0 0"/>
    <axis xyz="0 1 0"/>
    <dynamics damping="0.5" friction="0.1"/>
  </joint>
  <link name="cart_rr_wheel_link">
    <inertial>
      <mass value="5.0"/>
      <origin xyz="0 0 0" rpy="0 0 0"/>
      <inertia ixx="0.347" iyy="0.689" izz="0.347" ixy="0" ixz="0" iyz="0"/>
    </inertial>
    <visual>
      <origin xyz="0 0 0" rpy="1.5708 0 0"/>
      <geometry><cylinder radius="0.525" length="0.08"/></geometry>
      <material name="dark_grey"/>
    </visual>
    <collision>
      <origin xyz="0 0 0" rpy="1.5708 0 0"/>
      <geometry><cylinder radius="0.525" length="0.08"/></geometry>
    </collision>
  </link>

</robot>
